Workbook

Sheet Sheet1
A1: Maricopa | E1: Pima | F1: Pinal | J1: AZ
A2: day | B2: infected | D2: day | E2: infected | F2: infected | I2: day
A3: 0 | D3: 0 | I3: 0
A4: 31 | B4: {='CALENDAR YEAR 2013'!S18:S29} -> 514 | C4: 2013 | D4: 31 | E4: {='CALENDAR YEAR 2013'!V18:V29} -> 116.42857 | F4: {='CALENDAR YEAR 2013'!W18:W29} -> 48.857143 | H4: 2013 | I4: 31 | J4: {='CALENDAR YEAR 2013'!AA18:AA29} -> 726.28571
A5: 59 | B5: 323.71429 | D5: 59 | E5: 70.571429 | F5: 36.285714 | I5: 59 | J5: 461.57143
A6: 90 | B6: 232.71429 | D6: 90 | E6: 42.285714 | F6: 15.428571 | I6: 90 | J6: 326
A7: 120 | B7: 258.14286 | D7: 120 | E7: 62.571429 | F7: 17.714286 | I7: 120 | J7: 356.42857
A8: 151 | B8: 294.14286 | D8: 151 | E8: 71.714286 | F8: 34.142857 | I8: 151 | J8: 425
A9: 181 | B9: 286 | D9: 181 | E9: 88.285714 | F9: 33.571429 | I9: 181 | J9: 431.57143
A10: 212 | B10: 305 | D10: 212 | E10: 71.285714 | F10: 30.571429 | I10: 212 | J10: 431.42857
A11: 243 | B11: 324.28571 | D11: 243 | E11: 88.857143 | F11: 35.428571 | I11: 243 | J11: 463.71429
A12: 273 | B12: 281.42857 | D12: 273 | E12: 72.285714 | F12: 25.428571 | I12: 273 | J12: 401.14286
A13: 304 | B13: 337.28571 | D13: 304 | E13: 80.285714 | F13: 34.142857 | I13: 304 | J13: 489.71429
A14: 334 | B14: 500.28571 | D14: 334 | E14: 106.42857 | F14: 41.428571 | I14: 334 | J14: 682.14286
A15: 365 | B15: 460 | D15: 365 | E15: 137 | F15: 61 | I15: 365 | J15: 696
A16: 396 | B16: {='CALENDAR YEAR 2014'!S6:S17} -> 406.71429 | C16: 2014 | D16: 396 | E16: {='CALENDAR YEAR 2014'!V6:V17} -> 82.285714 | F16: {='CALENDAR YEAR 2014'!W6:W17} -> 38.857143 | H16: 2014 | I16: 396 | J16: {='CALENDAR YEAR 2014'!AA6:AA17} -> 564.85714
A17: 424 | B17: 439 | D17: 424 | E17: 91.857143 | F17: 35.142857 | I17: 424 | J17: 591.85714
A18: 455 | B18: 418.28571 | D18: 455 | E18: 77.285714 | F18: 54.857143 | I18: 455 | J18: 574
A19: 485 | B19: 372.28571 | D19: 485 | E19: 81.571429 | F19: 43.714286 | I19: 485 | J19: 529.28571
A20: 516 | B20: 419.71429 | D20: 516 | E20: 82 | F20: 57.428571 | I20: 516 | J20: 595
A21: 546 | B21: 353.14286 | D21: 546 | E21: 80.428571 | F21: 40.142857 | I21: 546 | J21: 505.14286
A22: 577 | B22: 227 | D22: 577 | E22: 46.571429 | F22: 27.428571 | I22: 577 | J22: 319.57143
A23: 608 | B23: 224.71429 | D23: 608 | E23: 62 | F23: 33.428571 | I23: 608 | J23: 347.85714
A24: 638 | B24: 253.28571 | D24: 638 | E24: 52.285714 | F24: 28.142857 | I24: 638 | J24: 352.28571
A25: 669 | B25: 223.14286 | D25: 669 | E25: 61 | F25: 22.285714 | I25: 669 | J25: 325.71429
A26: 699 | B26: 225.28571 | D26: 699 | E26: 57.142857 | F26: 30 | I26: 699 | J26: 338.85714
A27: 730 | B27: 315.42857 | D27: 730 | E27: 58.571429 | F27: 33.571429 | I27: 730 | J27: 435.57143
A28: 761 | B28: {='CALENDAR YEAR 2015'!S6:S17} -> 244 | C28: 2015 | D28: 761 | E28: {='CALENDAR YEAR 2015'!V6:V17} -> 96 | F28: {='CALENDAR YEAR 2015'!W6:W17} -> 37 | H28: 2015 | I28: 761 | J28: {='CALENDAR YEAR 2015'!AA6:AA17} -> 410
A29: 789 | B29: 268 | D29: 789 | E29: 66 | F29: 32 | I29: 789 | J29: 380
A30: 820 | B30: 312.28571 | D30: 820 | E30: 58.571429 | F30: 37.571429 | I30: 820 | J30: 432.57143
A31: 850 | B31: 364.28571 | D31: 850 | E31: 71.285714 | F31: 48.285714 | I31: 850 | J31: 517.42857
A32: 881 | B32: 331.57143 | D32: 881 | E32: 75 | F32: 42.142857 | I32: 881 | J32: 471.71429
A33: 911 | B33: 448.85714 | D33: 911 | E33: 148.14286 | F33: 48.714286 | I33: 911 | J33: 700.14286
A34: 942 | B34: 501.71429 | D34: 942 | E34: 115.71429 | F34: 60.428571 | I34: 942 | J34: 727.71429
A35: 973 | B35: 557.57143 | D35: 973 | E35: 112.85714 | F35: 68.714286 | I35: 973 | J35: 778.71429
A36: 1003 | B36: 674.28571 | D36: 1003 | E36: 146.28571 | F36: 71.285714 | I36: 1003 | J36: 944.57143
A37: 1034 | B37: 553.42857 | D37: 1034 | E37: 114.14286 | F37: 78.857143 | I37: 1034 | J37: 786.14286
A38: 1064 | B38: 586.28571 | D38: 1064 | E38: 109.14286 | F38: 73.142857 | I38: 1064 | J38: 800
A39: 1095 | B39: 505.71429 | D39: 1095 | E39: 86.857143 | F39: 56.857143 | I39: 1095 | J39: 684
A40: 1126 | B40: {='CALENDAR YEAR 2016'!S6:S17} -> 414.57143 | C40: 2016 | D40: 1126 | E40: {='CALENDAR YEAR 2016'!V6:V17} -> 80.285714 | F40: {='CALENDAR YEAR 2016'!W6:W17} -> 47.857143 | H40: 2016 | I40: 1126 | J40: {='CALENDAR YEAR 2016'!AA6:AA17} -> 581.28571
...

Sheet INTRODUCTION
A1: Frequency of Valley fever Cases by Event Date (Calendar Year) | D1: Frequency of missing cases by Event Date (Calendar Year) not included in designated excel sheets | H1: Frequency of cases reporting an unknown County by Event Date (Calendar Year); included in excel sheets
A2: Year | B2: Frequency | D2: Year | E2: Frequency | I2: Year | J2: Frequency
A3: 1997 | B3: 886 | D3: 1998 | E3: 68 | I3: 2004 | J3: 1
A4: =A3+1 -> 1998 | B4: 1483 | D4: 1999 | E4: 64 | I4: 1998 | J4: 1
A5: =A4+1 -> 1999 | B5: 1720 | D5: 2001 | E5: 4 | I5: 1997 | J5: 13
A6: =A5+1 -> 2000 | B6: 1880 | D6: 2002 | E6: 3
A7: =A6+1 -> 2001 | B7: 2364 | D7: 2003 | E7: 11
A8: =A7+1 -> 2002 | B8: 3146
A9: =A8+1 -> 2003 | B9: 2630 | D9: Notes
A10: =A9+1 -> 2004 | B10: 3679 | D10: The 'event date' variable was coded into calendar year/week. 'Event date' stands for the earliest date of Onset Date, Date Collected, Date Finaled, Diagnosis Date, Date Reported to County, Date Entered into MEDSIS, Date Reported to ADHS, or Date Submitted to State.
A11: =A10+1 -> 2005 | B11: 3465
A12: =A11+1 -> 2006 | B12: 5643 | D12: Cases on this excel sheet are counted by calendar month and year, not by MMWR epidemiologic year - so yearly totals may not perfectly align with ADHS reported statistics
A13: =A12+1 -> 2007 | B13: 4831
A14: =A13+1 -> 2008 | B14: 4759 | D14: Prior to 2006, communicable disease reports were largely received by fax or mail and manually reviewed against the state’s disease registry at the time. Robust state-wide surveillance data processes were limited due to limitations with the database. Therefore, data during this time should be interpreted with caution especially if compared to later years.
A15: =A14+1 -> 2009 | B15: 10255
A16: =A15+1 -> 2010 | B16: 11934 | D16: Lab-only case definition (i.e., no clinical criteria required) has been in use since 2008. Mandatory disease reporting by laboratories since 1997.
A17: =A16+1 -> 2011 | B17: 16419
A18: =A17+1 -> 2012 | B18: 12830 | D18: Empty data cells or those denoted by 0's, mean no observations were shown during that time period. | E18: Empty data cells or those denoted by 0's, mean no observations were shown during that time period. | F18: Empty data cells or those denoted by 0's, mean no observations were shown during that time period. | G18: Empty data cells or those denoted by 0's, mean no observations were shown during that time period.
A19: =A18+1 -> 2013 | B19: 5891
A20: =A19+1 -> 2014 | B20: 5480
A21: =A20+1 -> 2015 | B21: 7633
A22: =A21+1 -> 2016 | B22: 6154
A23: =A22+1 -> 2017 | B23: 6946
A24: =A23+1 -> 2018 | B24: 7487
A25: =A24+1 -> 2019 | B25: 10370
A26: =A25+1 -> 2020 | B26: 11423
A27: =A26+1 -> 2021 | B27: 11548
A28: =A27+1 -> 2022 | B28: 9459
A29: =A28+1 -> 2023 | B29: 10904

Sheet CALENDAR YEAR 2023
A1: CALENDAR YEAR 2023
A2: EVENT DATE by CALENDAR WEEK | B2: COUNTY | S2: Maricopa | V2: Pima | W2: Pinal | AA2: AZ
B3: APACHE | C3: COCHISE | D3: COCONINO | E3: GILA | F3: GRAHAM | G3: GREENLEE | H3: LA PAZ | I3: MARICOPA | J3: MOHAVE | K3: NAVAJO | L3: PIMA | M3: PINAL | N3: SANTA CRUZ | O3: YAVAPAI | P3: YUMA | Q3: Total
A4: 1 | B4: 0 | C4: 1 | D4: 2 | E4: 1 | F4: 0 | G4: 0 | H4: 0 | I4: 98 | J4: 1 | K4: 1 | L4: 30 | M4: 13 | N4: 0 | O4: 0 | P4: 2 | Q4: 149
A5: 2 | B5: 0 | C5: 0 | D5: 1 | E5: 2 | F5: 1 | G5: 0 | H5: 0 | I5: 111 | J5: 3 | K5: 3 | L5: 18 | M5: 15 | N5: 1 | O5: 0 | P5: 0 | Q5: 155 | T5: =0+365*10+2 -> 3652
A6: 3 | B6: 1 | C6: 1 | D6: 3 | E6: 1 | F6: 1 | G6: 0 | H6: 1 | I6: 115 | J6: 0 | K6: 2 | L6: 23 | M6: 12 | N6: 1 | O6: 2 | P6: 2 | Q6: 165 | R6: JAN. | S6: =SUM(I$4:I$7)+(3/7)*I$8 -> 501.42857 | T6: =31+365*10+2 -> 3683 | V6: =SUM(L$4:L$7)+(3/7)*L$8 -> 103.42857 | W6: =SUM(M$4:M$7)+(3/7)*M$8 -> 56.571429 | AA6: =SUM(Q$4:Q$7)+(3/7)*Q$8 -> 704.42857
A7: 4 | B7: 2 | C7: 0 | D7: 2 | E7: 0 | F7: 0 | G7: 0 | H7: 0 | I7: 129 | J7: 1 | K7: 0 | L7: 20 | M7: 14 | N7: 0 | O7: 1 | P7: 0 | Q7: 169 | R7: FEB. | S7: =(4/7)*I$8+SUM(I$9:I$11)+(3/7)*I$12 -> 433.28571 | T7: =T6+28 -> 3711 | V7: =(4/7)*L$8+SUM(L$9:L$11)+(3/7)*L$12 -> 87.571429 | W7: =(4/7)*M$8+SUM(M$9:M$11)+(3/7)*M$12 -> 49 | AA7: =(4/7)*Q$8+SUM(Q$9:Q$11)+(3/7)*Q$12 -> 615.28571
A8: 5 | B8: 0 | C8: 2 | D8: 1 | E8: 1 | F8: 0 | G8: 0 | H8: 1 | I8: 113 | J8: 1 | K8: 0 | L8: 29 | M8: 6 | N8: 0 | O8: 0 | P8: 1 | Q8: 155 | R8: MAR. | S8: =(4/7)*I$12+SUM(I$13:I$15)+(6/7)*I$16 -> 548.85714 | T8: =T7+31 -> 3742 | V8: =(4/7)*L$12+SUM(L$13:L$15)+(6/7)*L$16 -> 89 | W8: =(4/7)*M$12+SUM(M$13:M$15)+(6/7)*M$16 -> 62.571429 | AA8: =(4/7)*Q$12+SUM(Q$13:Q$15)+(6/7)*Q$16 -> 773.57143
A9: 6 | B9: 1 | C9: 1 | D9: 0 | E9: 0 | F9: 0 | G9: 0 | H9: 1 | I9: 117 | J9: 1 | K9: 3 | L9: 21 | M9: 16 | N9: 1 | O9: 3 | P9: 0 | Q9: 165 | R9: APR. | S9: =(1/7)*I$16+SUM(I$17:I$20)+(1/7)*I$21 -> 511.42857 | T9: =T8+30 -> 3772 | V9: =(1/7)*L$16+SUM(L$17:L$20)+(1/7)*L$21 -> 87.285714 | W9: =(1/7)*M$16+SUM(M$17:M$20)+(1/7)*M$21 -> 49.714286 | AA9: =(1/7)*Q$16+SUM(Q$17:Q$20)+(1/7)*Q$21 -> 702.42857
A10: 7 | B10: 1 | C10: 1 | D10: 3 | E10: 0 | F10: 0 | G10: 0 | H10: 0 | I10: 89 | J10: 4 | K10: 2 | L10: 23 | M10: 7 | N10: 2 | O10: 1 | P10: 1 | Q10: 134 | R10: MAY | S10: =(6/7)*I$21+SUM(I$22:I$24)+(4/7)*I$25 -> 542 | T10: =T9+31 -> 3803 | V10: =(6/7)*L$21+SUM(L$22:L$24)+(4/7)*L$25 -> 100.57143 | W10: =(6/7)*M$21+SUM(M$22:M$24)+(4/7)*M$25 -> 57.571429 | AA10: =(6/7)*Q$21+SUM(Q$22:Q$24)+(4/7)*Q$25 -> 750.71429
A11: 8 | B11: 0 | C11: 0 | D11: 1 | E11: 1 | F11: 1 | G11: 0 | H11: 0 | I11: 116 | J11: 1 | K11: 2 | L11: 21 | M11: 14 | N11: 0 | O11: 2 | P11: 1 | Q11: 160 | R11: JUN. | S11: =(3/7)*I$25+SUM(I$26:I$28)+(6/7)*I$29 -> 491.14286 | T11: =T10+30 -> 3833 | V11: =(3/7)*L$25+SUM(L$26:L$28)+(6/7)*L$29 -> 104 | W11: =(3/7)*M$25+SUM(M$26:M$28)+(6/7)*M$29 -> 59.571429 | AA11: =(3/7)*Q$25+SUM(Q$26:Q$28)+(6/7)*Q$29 -> 706
A12: 9 | B12: 2 | C12: 1 | D12: 1 | E12: 2 | F12: 2 | G12: 0 | H12: 1 | I12: 109 | J12: 2 | K12: 1 | L12: 14 | M12: 20 | N12: 1 | O12: 1 | P12: 1 | Q12: 158 | R12: JULY | S12: =(1/7)*I$29+SUM(I$30:I$33)+(2/7)*I$34 -> 609.71429 | T12: =T11+31 -> 3864 | V12: =(1/7)*L$29+SUM(L$30:L$33)+(2/7)*L$34 -> 109.42857 | W12: =(1/7)*M$29+SUM(M$30:M$33)+(2/7)*M$34 -> 100.57143 | AA12: =(1/7)*Q$29+SUM(Q$30:Q$33)+(2/7)*Q$34 -> 869.28571
A13: 10 | B13: 2 | C13: 1 | D13: 3 | E13: 3 | F13: 0 | G13: 0 | H13: 1 | I13: 135 | J13: 3 | K13: 0 | L13: 19 | M13: 15 | N13: 2 | O13: 3 | P13: 1 | Q13: 188 | R13: AUG. | S13: =(5/7)*I$34+SUM(I$35:I$37)+(5/7)*I$38 -> 704 | T13: =T12+31 -> 3895 | V13: =(5/7)*L$34+SUM(L$35:L$37)+(5/7)*L$38 -> 115.28571 | W13: =(5/7)*M$34+SUM(M$35:M$37)+(5/7)*M$38 -> 93.857143 | AA13: =(5/7)*Q$34+SUM(Q$35:Q$37)+(5/7)*Q$38 -> 974.42857
A14: 11 | B14: 2 | C14: 2 | D14: 2 | E14: 2 | F14: 1 | G14: 2 | H14: 1 | I14: 128 | J14: 0 | K14: 0 | L14: 26 | M14: 21 | N14: 1 | O14: 8 | P14: 0 | Q14: 196 | R14: SEP. | S14: =(2/7)*I$38+SUM(I$39:I$41)+(7/7)*I$42 -> 689.14286 | T14: =T13+30 -> 3925 | V14: =(2/7)*L$38+SUM(L$39:L$41)+(7/7)*L$42 -> 93.428571 | W14: =(2/7)*M$38+SUM(M$39:M$41)+(7/7)*M$42 -> 77.571429 | AA14: =(2/7)*Q$38+SUM(Q$39:Q$41)+(7/7)*Q$42 -> 929.85714
A15: 12 | B15: 0 | C15: 1 | D15: 2 | E15: 2 | F15: 1 | G15: 0 | H15: 1 | I15: 113 | J15: 3 | K15: 0 | L15: 18 | M15: 10 | N15: 0 | O15: 3 | P15: 3 | Q15: 157 | R15: OCT. | S15: =(0/7)*I$42+SUM(I$43:I$46)+(3/7)*I$47 -> 842.42857 | T15: =T14+31 -> 3956 | V15: =(0/7)*L$42+SUM(L$43:L$46)+(3/7)*L$47 -> 113.42857 | W15: =(0/7)*M$42+SUM(M$43:M$46)+(3/7)*M$47 -> 106.42857 | AA15: =(0/7)*Q$42+SUM(Q$43:Q$46)+(3/7)*Q$47 -> 1126
A16: 13 | B16: 1 | C16: 1 | D16: 0 | E16: 0 | F16: 0 | G16: 1 | H16: 0 | I16: 129 | J16: 5 | K16: 0 | L16: 21 | M16: 6 | N16: 0 | O16: 1 | P16: 1 | Q16: 166 | R16: NOV. | S16: =(4/7)*I$47+SUM(I$48:I$50)+(5/7)*I$51 -> 989.14286 | T16: =T15+30 -> 3986 | V16: =(4/7)*L$47+SUM(L$48:L$50)+(5/7)*L$51 -> 132 | W16: =(4/7)*M$47+SUM(M$48:M$50)+(5/7)*M$51 -> 131.42857 | AA16: =(4/7)*Q$47+SUM(Q$48:Q$50)+(5/7)*Q$51 -> 1335
A17: 14 | B17: 0 | C17: 4 | D17: 0 | E17: 0 | F17: 0 | G17: 0 | H17: 1 | I17: 117 | J17: 2 | K17: 0 | L17: 13 | M17: 10 | N17: 0 | O17: 2 | P17: 0 | Q17: 149 | R17: DEC. | S17: =(2/7)*I$51+SUM(I$52:I$55) -> 1072.4286 | T17: =T16+31 -> 4017 | V17: =(2/7)*L$51+SUM(L$52:L$55) -> 134.57143 | W17: =(2/7)*M$51+SUM(M$52:M$55) -> 141.14286 | AA17: =(2/7)*Q$51+SUM(Q$52:Q$55) -> 1417
A18: 15 | B18: 1 | C18: 2 | D18: 1 | E18: 0 | F18: 0 | G18: 0 | H18: 0 | I18: 121 | J18: 2 | K18: 0 | L18: 19 | M18: 10 | N18: 1 | O18: 0 | P18: 2 | Q18: 159 | R18: toal | S18: =SUM(S6:S17) -> 7935 | V18: =SUM(V6:V17) -> 1270 | W18: =SUM(W6:W17) -> 986 | AA18: =SUM(AA6:AA17) -> 10904
A19: 16 | B19: 2 | C19: 1 | D19: 1 | E19: 1 | F19: 0 | G19: 0 | H19: 0 | I19: 116 | J19: 2 | K19: 1 | L19: 28 | M19: 10 | N19: 1 | O19: 3 | P19: 2 | Q19: 168
A20: 17 | B20: 1 | C20: 3 | D20: 1 | E20: 1 | F20: 0 | G20: 0 | H20: 0 | I20: 121 | J20: 5 | K20: 2 | L20: 21 | M20: 17 | N20: 1 | O20: 2 | P20: 2 | Q20: 177
A21: 18 | B21: 0 | C21: 1 | D21: 3 | E21: 0 | F21: 0 | G21: 0 | H21: 0 | I21: 126 | J21: 3 | K21: 2 | L21: 23 | M21: 13 | N21: 0 | O21: 7 | P21: 2 | Q21: 180
A22: 19 | B22: 1 | C22: 0 | D22: 1 | E22: 1 | F22: 0 | G22: 0 | H22: 0 | I22: 121 | J22: 1 | K22: 1 | L22: 13 | M22: 13 | N22: 0 | O22: 3 | P22: 1 | Q22: 156
A23: 20 | B23: 1 | C23: 1 | D23: 1 | E23: 1 | F23: 0 | G23: 0 | H23: 0 | I23: 133 | J23: 2 | K23: 2 | L23: 24 | M23: 10 | N23: 1 | O23: 3 | P23: 0 | Q23: 179
A24: 21 | B24: 1 | C24: 0 | D24: 2 | E24: 5 | F24: 0 | G24: 1 | H24: 0 | I24: 116 | J24: 0 | K24: 0 | L24: 29 | M24: 20 | N24: 0 | O24: 0 | P24: 0 | Q24: 174
A25: 22 | B25: 1 | C25: 2 | D25: 1 | E25: 1 | F25: 0 | G25: 0 | H25: 0 | I25: 112 | J25: 0 | K25: 1 | L25: 26 | M25: 6 | N25: 0 | O25: 3 | P25: 0 | Q25: 153
A26: 23 | B26: 1 | C26: 2 | D26: 2 | E26: 1 | F26: 1 | G26: 0 | H26: 1 | I26: 118 | J26: 3 | K26: 0 | L26: 30 | M26: 19 | N26: 0 | O26: 3 | P26: 0 | Q26: 181
A27: 24 | B27: 0 | C27: 1 | D27: 1 | E27: 2 | F27: 1 | G27: 1 | H27: 0 | I27: 111 | J27: 2 | K27: 2 | L27: 20 | M27: 8 | N27: 0 | O27: 1 | P27: 2 | Q27: 152
A28: 25 | B28: 0 | C28: 0 | D28: 1 | E28: 1 | F28: 1 | G28: 0 | H28: 0 | I28: 101 | J28: 1 | K28: 3 | L28: 24 | M28: 18 | N28: 0 | O28: 3 | P28: 1 | Q28: 154
A29: 26 | B29: 0 | C29: 4 | D29: 2 | E29: 2 | F29: 0 | G29: 0 | H29: 0 | I29: 132 | J29: 0 | K29: 2 | L29: 22 | M29: 14 | N29: 0 | O29: 0 | P29: 1 | Q29: 179
A30: 27 | B30: 0 | C30: 0 | D30: 1 | E30: 1 | F30: 0 | G30: 0 | H30: 0 | I30: 108 | J30: 2 | K30: 1 | L30: 21 | M30: 20 | N30: 0 | O30: 1 | P30: 1 | Q30: 156
... A55: 52 | B55: 1 | C55: 1 | D55: 3 | E55: 0 | F55: 0 | G55: 0 | H55: 0 | I55: 136 | J55: 1 | K55: 1 | L55: 12 | M55: 21 | N55: 0 | O55: 1 | P55: 1 | Q55: 178
A56: Total | B56: 46 | C56: 61 | D56: 81 | E56: 57 | F56: 21 | G56: 7 | H56: 23 | I56: 7935 | J56: 128 | K56: 72 | L56: 1270 | M56: 986 | N56: 24 | O56: 135 | P56: 58 | Q56: 10904

Sheet CALENDAR YEAR 2022
A1: CALENDAR YEAR 2022
A2: EVENT DATE by CALENDAR WEEK | B2: COUNTY | S2: Maricopa | V2: Pima | W2: Pinal | AA2: AZ
B3: APACHE | C3: COCHISE | D3: COCONINO | E3: GILA | F3: GRAHAM | G3: GREENLEE | H3: LA PAZ | I3: MARICOPA | J3: MOHAVE | K3: NAVAJO | L3: PIMA | M3: PINAL | N3: SANTA CRUZ | O3: YAVAPAI | P3: YUMA | Q3: Total
A4: 0 | B4: 0 | C4: 0 | D4: 0 | E4: 0 | F4: 0 | G4: 0 | H4: 0 | I4: 5 | J4: 0 | K4: 0 | L4: 1 | M4: 1 | N4: 0 | O4: 0 | P4: 1 | Q4: 8
A5: 1 | B5: 0 | C5: 0 | D5: 0 | E5: 0 | F5: 1 | G5: 0 | H5: 2 | I5: 187 | J5: 3 | K5: 4 | L5: 32 | M5: 25 | N5: 0 | O5: 0 | P5: 1 | Q5: 255 | T5: =0+365*9+2 -> 3287
A6: 2 | B6: 1 | C6: 4 | D6: 0 | E6: 2 | F6: 2 | G6: 0 | H6: 2 | I6: 194 | J6: 2 | K6: 0 | L6: 27 | M6: 27 | N6: 1 | O6: 1 | P6: 3 | Q6: 266 | R6: JAN. | S6: =SUM(I$4:I$8)+(2/7)*I$9 -> 708.85714 | T6: =31+365*9+2 -> 3318 | V6: =SUM(L$4:L$8)+(2/7)*L$9 -> 95.428571 | W6: =SUM(M$4:M$8)+(2/7)*M$9 -> 99.857143 | AA6: =SUM(Q$4:Q$8)+(2/7)*Q$9 -> 952.85714
A7: 3 | B7: 0 | C7: 1 | D7: 0 | E7: 1 | F7: 0 | G7: 0 | H7: 1 | I7: 158 | J7: 2 | K7: 0 | L7: 11 | M7: 19 | N7: 0 | O7: 3 | P7: 0 | Q7: 196 | R7: FEB. | S7: =(5/7)*I$9+SUM(I$10:I$12)+(2/7)*I$13 -> 514.28571 | T7: =T6+28 -> 3346 | V7: =(5/7)*L$9+SUM(L$10:L$12)+(2/7)*L$13 -> 57.142857 | W7: =(5/7)*M$9+SUM(M$10:M$12)+(2/7)*M$13 -> 66.428571 | AA7: =(5/7)*Q$9+SUM(Q$10:Q$12)+(2/7)*Q$13 -> 673.57143
A8: 4 | B8: 0 | C8: 0 | D8: 1 | E8: 0 | F8: 0 | G8: 0 | H8: 0 | I8: 128 | J8: 2 | K8: 1 | L8: 19 | M8: 23 | N8: 0 | O8: 2 | P8: 3 | Q8: 179 | R8: MAR. | S8: =(5/7)*I$13+SUM(I$14:I$16)+(5/7)*I$17 -> 501.71429 | T8: =T7+31 -> 3377 | V8: =(5/7)*L$13+SUM(L$14:L$16)+(5/7)*L$17 -> 83.857143 | W8: =(5/7)*M$13+SUM(M$14:M$16)+(5/7)*M$17 -> 74 | AA8: =(5/7)*Q$13+SUM(Q$14:Q$16)+(5/7)*Q$17 -> 704.57143
A9: 5 | B9: 0 | C9: 1 | D9: 0 | E9: 1 | F9: 0 | G9: 0 | H9: 2 | I9: 129 | J9: 0 | K9: 0 | L9: 19 | M9: 17 | N9: 0 | O9: 1 | P9: 1 | Q9: 171 | R9: APR. | S9: =(2/7)*I$17+SUM(I$18:I$20)+(7/7)*I$21 -> 593.14286 | T9: =T8+30 -> 3407 | V9: =(2/7)*L$17+SUM(L$18:L$20)+(7/7)*L$21 -> 83.571429 | W9: =(2/7)*M$17+SUM(M$18:M$20)+(7/7)*M$21 -> 69.714286 | AA9: =(2/7)*Q$17+SUM(Q$18:Q$20)+(7/7)*Q$21 -> 787
A10: 6 | B10: 1 | C10: 2 | D10: 0 | E10: 0 | F10: 1 | G10: 0 | H10: 0 | I10: 130 | J10: 1 | K10: 0 | L10: 9 | M10: 17 | N10: 0 | O10: 1 | P10: 0 | Q10: 162 | R10: MAY | S10: =(0/7)*I$21+SUM(I$22:I$25)+(3/7)*I$26 -> 692.57143 | T10: =T9+31 -> 3438 | V10: =(0/7)*L$21+SUM(L$22:L$25)+(3/7)*L$26 -> 112.28571 | W10: =(0/7)*M$21+SUM(M$22:M$25)+(3/7)*M$26 -> 79.285714 | AA10: =(0/7)*Q$21+SUM(Q$22:Q$25)+(3/7)*Q$26 -> 948.14286
A11: 7 | B11: 0 | C11: 1 | D11: 2 | E11: 1 | F11: 1 | G11: 0 | H11: 0 | I11: 137 | J11: 2 | K11: 1 | L11: 11 | M11: 16 | N11: 1 | O11: 2 | P11: 0 | Q11: 175 | R11: JUN. | S11: =(4/7)*I$26+SUM(I$27:I$29)+(5/7)*I$30 -> 669.71429 | T11: =T10+30 -> 3468 | V11: =(4/7)*L$26+SUM(L$27:L$29)+(5/7)*L$30 -> 113.85714 | W11: =(4/7)*M$26+SUM(M$27:M$29)+(5/7)*M$30 -> 73.857143 | AA11: =(4/7)*Q$26+SUM(Q$27:Q$29)+(5/7)*Q$30 -> 911.28571
A12: 8 | B12: 0 | C12: 2 | D12: 1 | E12: 0 | F12: 0 | G12: 0 | H12: 2 | I12: 120 | J12: 3 | K12: 0 | L12: 17 | M12: 15 | N12: 0 | O12: 0 | P12: 1 | Q12: 161 | R12: JULY | S12: =(2/7)*I$30+SUM(I$31:I$34)+(1/7)*I$35 -> 773.71429 | T12: =T11+31 -> 3499 | V12: =(2/7)*L$30+SUM(L$31:L$34)+(1/7)*L$35 -> 139.71429 | W12: =(2/7)*M$30+SUM(M$31:M$34)+(1/7)*M$35 -> 95.285714 | AA12: =(2/7)*Q$30+SUM(Q$31:Q$34)+(1/7)*Q$35 -> 1072.5714
A13: 9 | B13: 2 | C13: 0 | D13: 1 | E13: 2 | F13: 3 | G13: 1 | H13: 1 | I13: 123 | J13: 5 | K13: 0 | L13: 23 | M13: 22 | N13: 0 | O13: 2 | P13: 2 | Q13: 187 | R13: AUG. | S13: =(6/7)*I$35+SUM(I$36:I$38)+(4/7)*I$39 -> 525.57143 | T13: =T12+31 -> 3530 | V13: =(6/7)*L$35+SUM(L$36:L$38)+(4/7)*L$39 -> 100.57143 | W13: =(6/7)*M$35+SUM(M$36:M$38)+(4/7)*M$39 -> 49.285714 | AA13: =(6/7)*Q$35+SUM(Q$36:Q$38)+(4/7)*Q$39 -> 715.71429
A14: 10 | B14: 0 | C14: 0 | D14: 0 | E14: 4 | F14: 2 | G14: 0 | H14: 1 | I14: 104 | J14: 1 | K14: 0 | L14: 17 | M14: 18 | N14: 1 | O14: 0 | P14: 0 | Q14: 148 | R14: SEP. | S14: =(3/7)*I$39+SUM(I$40:I$42)+(6/7)*I$43 -> 442.71429 | T14: =T13+30 -> 3560 | V14: =(3/7)*L$39+SUM(L$40:L$42)+(6/7)*L$43 -> 81.714286 | W14: =(3/7)*M$39+SUM(M$40:M$42)+(6/7)*M$43 -> 50.857143 | AA14: =(3/7)*Q$39+SUM(Q$40:Q$42)+(6/7)*Q$43 -> 625.85714
A15: 11 | B15: 0 | C15: 1 | D15: 1 | E15: 0 | F15: 0 | G15: 0 | H15: 0 | I15: 108 | J15: 2 | K15: 2 | L15: 21 | M15: 14 | N15: 1 | O15: 2 | P15: 1 | Q15: 153 | R15: OCT. | S15: =(1/7)*I$43+SUM(I$44:I$47)+(2/7)*I$48 -> 430.42857 | T15: =T14+31 -> 3591 | V15: =(1/7)*L$43+SUM(L$44:L$47)+(2/7)*L$48 -> 89.142857 | W15: =(1/7)*M$43+SUM(M$44:M$47)+(2/7)*M$48 -> 50.714286 | AA15: =(1/7)*Q$43+SUM(Q$44:Q$47)+(2/7)*Q$48 -> 617.14286
A16: 12 | B16: 1 | C16: 0 | D16: 1 | E16: 0 | F16: 0 | G16: 0 | H16: 1 | I16: 104 | J16: 2 | K16: 0 | L16: 18 | M16: 12 | N16: 0 | O16: 1 | P16: 0 | Q16: 140 | R16: NOV. | S16: =(5/7)*I$48+SUM(I$49:I$51)+(4/7)*I$52 -> 514.14286 | T16: =T15+30 -> 3621 | V16: =(5/7)*L$48+SUM(L$49:L$51)+(4/7)*L$52 -> 79 | W16: =(5/7)*M$48+SUM(M$49:M$51)+(4/7)*M$52 -> 61.142857 | AA16: =(5/7)*Q$48+SUM(Q$49:Q$51)+(4/7)*Q$52 -> 691.28571
A17: 13 | B17: 0 | C17: 1 | D17: 1 | E17: 0 | F17: 0 | G17: 0 | H17: 0 | I17: 137 | J17: 1 | K17: 0 | L17: 16 | M17: 20 | N17: 0 | O17: 4 | P17: 2 | Q17: 182 | R17: DEC. | S17: =(3/7)*I$52+SUM(I$53:I$55)+(7/7)*I$56 -> 558.14286 | T17: =T16+31 -> 3652 | V17: =(3/7)*L$52+SUM(L$53:L$55)+(7/7)*L$56 -> 93.714286 | W17: =(3/7)*M$52+SUM(M$53:M$55)+(7/7)*M$56 -> 70.571429 | AA17: =(3/7)*Q$52+SUM(Q$53:Q$55)+(7/7)*Q$56 -> 759
A18: 14 | B18: 1 | C18: 0 | D18: 1 | E18: 1 | F18: 0 | G18: 0 | H18: 1 | I18: 131 | J18: 1 | K18: 0 | L18: 13 | M18: 19 | N18: 1 | O18: 0 | P18: 2 | Q18: 171 | R18: toal | S18: =SUM(S6:S17) -> 6925 | V18: =SUM(V6:V17) -> 1130 | W18: =SUM(W6:W17) -> 841 | AA18: =SUM(AA6:AA17) -> 9459
A19: 15 | B19: 0 | C19: 2 | D19: 1 | E19: 2 | F19: 0 | G19: 0 | H19: 0 | I19: 132 | J19: 5 | K19: 0 | L19: 21 | M19: 13 | N19: 0 | O19: 1 | P19: 1 | Q19: 178
A20: 16 | B20: 0 | C20: 0 | D20: 0 | E20: 0 | F20: 0 | G20: 0 | H20: 0 | I20: 144 | J20: 6 | K20: 1 | L20: 21 | M20: 9 | N20: 0 | O20: 1 | P20: 1 | Q20: 183
A21: 17 | B21: 2 | C21: 2 | D21: 0 | E21: 0 | F21: 1 | G21: 0 | H21: 0 | I21: 147 | J21: 2 | K21: 0 | L21: 24 | M21: 23 | N21: 0 | O21: 1 | P21: 1 | Q21: 203
A22: 18 | B22: 2 | C22: 3 | D22: 1 | E22: 0 | F22: 0 | G22: 0 | H22: 0 | I22: 165 | J22: 8 | K22: 1 | L22: 27 | M22: 16 | N22: 1 | O22: 2 | P22: 1 | Q22: 227
A23: 19 | B23: 2 | C23: 4 | D23: 1 | E23: 2 | F23: 1 | G23: 1 | H23: 0 | I23: 150 | J23: 0 | K23: 4 | L23: 24 | M23: 20 | N23: 0 | O23: 2 | P23: 0 | Q23: 211
A24: 20 | B24: 0 | C24: 1 | D24: 0 | E24: 0 | F24: 0 | G24: 0 | H24: 0 | I24: 177 | J24: 4 | K24: 0 | L24: 34 | M24: 16 | N24: 2 | O24: 3 | P24: 0 | Q24: 237
A25: 21 | B25: 0 | C25: 1 | D25: 2 | E25: 0 | F25: 0 | G25: 0 | H25: 1 | I25: 144 | J25: 5 | K25: 1 | L25: 17 | M25: 20 | N25: 0 | O25: 1 | P25: 1 | Q25: 193
A26: 22 | B26: 0 | C26: 1 | D26: 1 | E26: 2 | F26: 0 | G26: 0 | H26: 1 | I26: 132 | J26: 4 | K26: 1 | L26: 24 | M26: 17 | N26: 0 | O26: 3 | P26: 1 | Q26: 187
A27: 23 | B27: 1 | C27: 1 | D27: 0 | E27: 1 | F27: 0 | G27: 0 | H27: 0 | I27: 158 | J27: 3 | K27: 2 | L27: 26 | M27: 19 | N27: 2 | O27: 2 | P27: 2 | Q27: 217
A28: 24 | B28: 0 | C28: 1 | D28: 0 | E28: 1 | F28: 0 | G28: 0 | H28: 1 | I28: 163 | J28: 4 | K28: 0 | L28: 25 | M28: 20 | N28: 1 | O28: 2 | P28: 1 | Q28: 219
A29: 25 | B29: 0 | C29: 2 | D29: 1 | E29: 1 | F29: 1 | G29: 0 | H29: 0 | I29: 154 | J29: 1 | K29: 0 | L29: 32 | M29: 13 | N29: 0 | O29: 2 | P29: 0 | Q29: 207
A30: 26 | B30: 0 | C30: 1 | D30: 2 | E30: 1 | F30: 0 | G30: 0 | H30: 1 | I30: 167 | J30: 4 | K30: 0 | L30: 24 | M30: 17 | N30: 1 | O30: 6 | P30: 2 | Q30: 226
... A56: 52 | B56: 0 | C56: 0 | D56: 1 | E56: 2 | F56: 0 | G56: 0 | H56: 0 | I56: 90 | J56: 1 | K56: 0 | L56: 18 | M56: 14 | N56: 0 | O56: 2 | P56: 0 | Q56: 128
A57: Total | B57: 30 | C57: 65 | D57: 39 | E57: 44 | F57: 30 | G57: 3 | H57: 27 | I57: 6925 | J57: 125 | K57: 36 | L57: 1130 | M57: 841 | N57: 19 | O57: 92 | P57: 53 | Q57: 9459

Sheet CALENDAR YEAR 2021
A1: CALENDAR YEAR 2021
A2: EVENT DATE by CALENDAR WEEK | B2: COUNTY | S2: Maricopa | V2: Pima | W2: Pinal | AA2: AZ
B3: APACHE | C3: COCHISE | D3: COCONINO | E3: GILA | F3: GRAHAM | G3: GREENLEE | H3: LA PAZ | I3: MARICOPA | J3: MOHAVE | K3: NAVAJO | L3: PIMA | M3: PINAL | N3: SANTA CRUZ | O3: YAVAPAI | P3: YUMA | Q3: Total
A4: 0 | B4: 0 | C4: 0 | D4: 1 | E4: 2 | F4: 1 | G4: 0 | H4: 0 | I4: 22 | J4: 0 | K4: 2 | L4: 4 | M4: 5 | N4: 0 | O4: 0 | P4: 0 | Q4: 37
A5: 1 | B5: 0 | C5: 2 | D5: 2 | E5: 1 | F5: 0 | G5: 0 | H5: 0 | I5: 234 | J5: 1 | K5: 2 | L5: 30 | M5: 24 | N5: 3 | O5: 2 | P5: 0 | Q5: 301 | T5: =0+365*8+2 -> 2922
A6: 2 | B6: 0 | C6: 1 | D6: 3 | E6: 1 | F6: 0 | G6: 0 | H6: 4 | I6: 251 | J6: 1 | K6: 2 | L6: 37 | M6: 35 | N6: 0 | O6: 1 | P6: 0 | Q6: 336 | R6: JAN. | S6: =SUM(I$4:I$8)+(1/7)*I$9 -> 994.28571 | T6: =31+365*8+2 -> 2953 | V6: =SUM(L$4:L$8)+(1/7)*L$9 -> 138.57143 | W6: =SUM(M$4:M$8)+(1/7)*M$9 -> 117.14286 | AA6: =SUM(Q$4:Q$8)+(1/7)*Q$9 -> 1323.2857
A7: 3 | B7: 3 | C7: 1 | D7: 1 | E7: 0 | F7: 0 | G7: 0 | H7: 1 | I7: 251 | J7: 6 | K7: 2 | L7: 27 | M7: 32 | N7: 0 | O7: 3 | P7: 3 | Q7: 330 | R7: FEB. | S7: =(6/7)*I$9+SUM(I$10:I$12)+(1/7)*I$13 -> 804.71429 | T7: =T6+28 -> 2981 | V7: =(6/7)*L$9+SUM(L$10:L$12)+(1/7)*L$13 -> 138.28571 | W7: =(6/7)*M$9+SUM(M$10:M$12)+(1/7)*M$13 -> 99 | AA7: =(6/7)*Q$9+SUM(Q$10:Q$12)+(1/7)*Q$13 -> 1113.4286
A8: 4 | B8: 2 | C8: 3 | D8: 0 | E8: 3 | F8: 0 | G8: 0 | H8: 2 | I8: 206 | J8: 4 | K8: 2 | L8: 35 | M8: 17 | N8: 1 | O8: 2 | P8: 0 | Q8: 277 | R8: MAR. | S8: =(6/7)*I$13+SUM(I$14:I$16)+(4/7)*I$17 -> 829.42857 | T8: =T7+31 -> 3012 | V8: =(6/7)*L$13+SUM(L$14:L$16)+(4/7)*L$17 -> 140.71429 | W8: =(6/7)*M$13+SUM(M$14:M$16)+(4/7)*M$17 -> 105.85714 | AA8: =(6/7)*Q$13+SUM(Q$14:Q$16)+(4/7)*Q$17 -> 1147.2857
A9: 5 | B9: 0 | C9: 2 | D9: 1 | E9: 2 | F9: 2 | G9: 0 | H9: 0 | I9: 212 | J9: 2 | K9: 3 | L9: 39 | M9: 29 | N9: 0 | O9: 3 | P9: 1 | Q9: 296 | R9: APR. | S9: =(3/7)*I$17+SUM(I$18:I$20)+(6/7)*I$21 -> 637.57143 | T9: =T8+30 -> 3042 | V9: =(3/7)*L$17+SUM(L$18:L$20)+(6/7)*L$21 -> 88.142857 | W9: =(3/7)*M$17+SUM(M$18:M$20)+(6/7)*M$21 -> 76.571429 | AA9: =(3/7)*Q$17+SUM(Q$18:Q$20)+(6/7)*Q$21 -> 863.14286
A10: 6 | B10: 2 | C10: 1 | D10: 1 | E10: 2 | F10: 0 | G10: 0 | H10: 4 | I10: 199 | J10: 2 | K10: 4 | L10: 35 | M10: 23 | N10: 1 | O10: 3 | P10: 1 | Q10: 278 | R10: MAY | S10: =(1/7)*I$21+SUM(I$22:I$25)+(2/7)*I$26 -> 620.85714 | T10: =T9+31 -> 3073 | V10: =(1/7)*L$21+SUM(L$22:L$25)+(2/7)*L$26 -> 110 | W10: =(1/7)*M$21+SUM(M$22:M$25)+(2/7)*M$26 -> 62.571429 | AA10: =(1/7)*Q$21+SUM(Q$22:Q$25)+(2/7)*Q$26 -> 854.42857
A11: 7 | B11: 0 | C11: 1 | D11: 0 | E11: 2 | F11: 0 | G11: 0 | H11: 1 | I11: 185 | J11: 7 | K11: 3 | L11: 32 | M11: 19 | N11: 1 | O11: 2 | P11: 0 | Q11: 253 | R11: JUN. | S11: =(5/7)*I$26+SUM(I$27:I$29)+(4/7)*I$30 -> 605.71429 | T11: =T10+30 -> 3103 | V11: =(5/7)*L$26+SUM(L$27:L$29)+(4/7)*L$30 -> 104.57143 | W11: =(5/7)*M$26+SUM(M$27:M$29)+(4/7)*M$30 -> 58.142857 | AA11: =(5/7)*Q$26+SUM(Q$27:Q$29)+(4/7)*Q$30 -> 809
A12: 8 | B12: 2 | C12: 1 | D12: 3 | E12: 3 | F12: 0 | G12: 1 | H12: 0 | I12: 209 | J12: 2 | K12: 0 | L12: 33 | M12: 29 | N12: 2 | O12: 1 | P12: 2 | Q12: 288 | R12: JULY | S12: =(3/7)*I$30+SUM(I$31:I$33)+(7/7)*I$34 -> 571.42857 | T12: =T11+31 -> 3134 | V12: =(3/7)*L$30+SUM(L$31:L$33)+(7/7)*L$34 -> 117.71429 | W12: =(3/7)*M$30+SUM(M$31:M$33)+(7/7)*M$34 -> 73.714286 | AA12: =(3/7)*Q$30+SUM(Q$31:Q$33)+(7/7)*Q$34 -> 814.42857
A13: 9 | B13: 1 | C13: 4 | D13: 3 | E13: 1 | F13: 0 | G13: 0 | H13: 0 | I13: 210 | J13: 6 | K13: 0 | L13: 34 | M13: 22 | N13: 1 | O13: 2 | P13: 1 | Q13: 285 | R13: AUG. | S13: =(0/7)*I$34+SUM(I$35:I$38)+(3/7)*I$39 -> 613.85714 | T13: =T12+31 -> 3165 | V13: =(0/7)*L$34+SUM(L$35:L$38)+(3/7)*L$39 -> 84.285714 | W13: =(0/7)*M$34+SUM(M$35:M$38)+(3/7)*M$39 -> 62.428571 | AA13: =(0/7)*Q$34+SUM(Q$35:Q$38)+(3/7)*Q$39 -> 810.71429
A14: 10 | B14: 0 | C14: 2 | D14: 1 | E14: 3 | F14: 2 | G14: 1 | H14: 1 | I14: 202 | J14: 3 | K14: 2 | L14: 31 | M14: 23 | N14: 0 | O14: 2 | P14: 3 | Q14: 276 | R14: SEP. | S14: =(4/7)*I$39+SUM(I$40:I$42)+(5/7)*I$43 -> 529.42857 | T14: =T13+30 -> 3195 | V14: =(4/7)*L$39+SUM(L$40:L$42)+(5/7)*L$43 -> 80.142857 | W14: =(4/7)*M$39+SUM(M$40:M$42)+(5/7)*M$43 -> 61.285714 | AA14: =(4/7)*Q$39+SUM(Q$40:Q$42)+(5/7)*Q$43 -> 736.71429
A15: 11 | B15: 0 | C15: 0 | D15: 0 | E15: 0 | F15: 0 | G15: 0 | H15: 1 | I15: 175 | J15: 3 | K15: 0 | L15: 35 | M15: 24 | N15: 0 | O15: 3 | P15: 2 | Q15: 243 | R15: OCT. | S15: =(2/7)*I$43+SUM(I$44:I$47)+(1/7)*I$48 -> 646.14286 | T15: =T14+31 -> 3226 | V15: =(2/7)*L$43+SUM(L$44:L$47)+(1/7)*L$48 -> 92.142857 | W15: =(2/7)*M$43+SUM(M$44:M$47)+(1/7)*M$48 -> 65.857143 | AA15: =(2/7)*Q$43+SUM(Q$44:Q$47)+(1/7)*Q$48 -> 842
A16: 12 | B16: 1 | C16: 1 | D16: 3 | E16: 1 | F16: 0 | G16: 0 | H16: 0 | I16: 185 | J16: 3 | K16: 2 | L16: 33 | M16: 28 | N16: 1 | O16: 2 | P16: 0 | Q16: 260 | R16: NOV. | S16: =(6/7)*I$48+SUM(I$49:I$51)+(3/7)*I$52 -> 773.28571 | T16: =T15+30 -> 3256 | V16: =(6/7)*L$48+SUM(L$49:L$51)+(3/7)*L$52 -> 98.857143 | W16: =(6/7)*M$48+SUM(M$49:M$51)+(3/7)*M$52 -> 78.571429 | AA16: =(6/7)*Q$48+SUM(Q$49:Q$51)+(3/7)*Q$52 -> 1009.8571
A17: 13 | B17: 0 | C17: 1 | D17: 1 | E17: 1 | F17: 0 | G17: 0 | H17: 0 | I17: 153 | J17: 4 | K17: 2 | L17: 22 | M17: 21 | N17: 2 | O17: 8 | P17: 2 | Q17: 217 | R17: DEC. | S17: =(4/7)*I$52+SUM(I$53:I$55)+(7/7)*I$56 -> 919.28571 | T17: =T16+31 -> 3287 | V17: =(4/7)*L$52+SUM(L$53:L$55)+(7/7)*L$56 -> 123.57143 | W17: =(4/7)*M$52+SUM(M$53:M$55)+(7/7)*M$56 -> 133.85714 | AA17: =(4/7)*Q$52+SUM(Q$53:Q$55)+(7/7)*Q$56 -> 1223.7143
A18: 14 | B18: 0 | C18: 3 | D18: 2 | E18: 1 | F18: 1 | G18: 0 | H18: 2 | I18: 165 | J18: 5 | K18: 0 | L18: 24 | M18: 27 | N18: 0 | O18: 6 | P18: 1 | Q18: 237 | R18: toal | S18: =SUM(S6:S17) -> 8546 | V18: =SUM(V6:V17) -> 1317 | W18: =SUM(W6:W17) -> 995 | AA18: =SUM(AA6:AA17) -> 11548
A19: 15 | B19: 0 | C19: 2 | D19: 0 | E19: 1 | F19: 0 | G19: 0 | H19: 0 | I19: 118 | J19: 1 | K19: 0 | L19: 21 | M19: 14 | N19: 2 | O19: 3 | P19: 1 | Q19: 163
A20: 16 | B20: 0 | C20: 0 | D20: 0 | E20: 0 | F20: 1 | G20: 0 | H20: 0 | I20: 169 | J20: 3 | K20: 4 | L20: 20 | M20: 12 | N20: 0 | O20: 3 | P20: 3 | Q20: 215
A21: 17 | B21: 1 | C21: 0 | D21: 1 | E21: 0 | F21: 1 | G21: 0 | H21: 0 | I21: 140 | J21: 1 | K21: 1 | L21: 16 | M21: 17 | N21: 0 | O21: 2 | P21: 1 | Q21: 181
A22: 18 | B22: 1 | C22: 3 | D22: 1 | E22: 1 | F22: 0 | G22: 0 | H22: 0 | I22: 133 | J22: 1 | K22: 0 | L22: 25 | M22: 19 | N22: 0 | O22: 5 | P22: 2 | Q22: 191
A23: 19 | B23: 0 | C23: 2 | D23: 1 | E23: 0 | F23: 0 | G23: 0 | H23: 0 | I23: 150 | J23: 6 | K23: 0 | L23: 28 | M23: 17 | N23: 1 | O23: 2 | P23: 2 | Q23: 209
A24: 20 | B24: 0 | C24: 3 | D24: 1 | E24: 0 | F24: 1 | G24: 0 | H24: 1 | I24: 151 | J24: 2 | K24: 2 | L24: 29 | M24: 8 | N24: 3 | O24: 3 | P24: 1 | Q24: 205
A25: 21 | B25: 0 | C25: 1 | D25: 1 | E25: 2 | F25: 1 | G25: 0 | H25: 1 | I25: 130 | J25: 1 | K25: 2 | L25: 20 | M25: 13 | N25: 1 | O25: 0 | P25: 2 | Q25: 175
A26: 22 | B26: 0 | C26: 0 | D26: 0 | E26: 1 | F26: 0 | G26: 0 | H26: 0 | I26: 129 | J26: 1 | K26: 2 | L26: 20 | M26: 11 | N26: 0 | O26: 5 | P26: 1 | Q26: 170
A27: 23 | B27: 1 | C27: 2 | D27: 0 | E27: 0 | F27: 0 | G27: 0 | H27: 0 | I27: 147 | J27: 3 | K27: 0 | L27: 23 | M27: 16 | N27: 0 | O27: 2 | P27: 0 | Q27: 194
A28: 24 | B28: 0 | C28: 0 | D28: 2 | E28: 0 | F28: 1 | G28: 0 | H28: 0 | I28: 162 | J28: 3 | K28: 0 | L28: 27 | M28: 10 | N28: 0 | O28: 2 | P28: 0 | Q28: 207
A29: 25 | B29: 0 | C29: 2 | D29: 0 | E29: 3 | F29: 0 | G29: 0 | H29: 0 | I29: 124 | J29: 3 | K29: 0 | L29: 26 | M29: 14 | N29: 0 | O29: 1 | P29: 1 | Q29: 174
A30: 26 | B30: 2 | C30: 2 | D30: 1 | E30: 0 | F30: 0 | G30: 0 | H30: 0 | I30: 141 | J30: 3 | K30: 1 | L30: 25 | M30: 18 | N30: 1 | O30: 1 | P30: 2 | Q30: 197
... A56: 52 | B56: 0 | C56: 0 | D56: 1 | E56: 0 | F56: 0 | G56: 0 | H56: 2 | I56: 163 | J56: 0 | K56: 1 | L56: 14 | M56: 23 | N56: 1 | O56: 0 | P56: 0 | Q56: 205
A57: Total | B57: 27 | C57: 66 | D57: 53 | E57: 57 | F57: 19 | G57: 2 | H57: 35 | I57: 8546 | J57: 150 | K57: 72 | L57: 1317 | M57: 995 | N57: 25 | O57: 127 | P57: 57 | Q57: 11548

Sheet CALENDAR YEAR 2020
A1: CALENDAR YEAR 2020
A2: EVENT DATE by CALENDAR WEEK | B2: COUNTY | S2: Maricopa | V2: Pima | W2: Pinal | AA2: AZ
B3: APACHE | C3: COCHISE | D3: COCONINO | E3: GILA | F3: GRAHAM | G3: GREENLEE | H3: LA PAZ | I3: MARICOPA | J3: MOHAVE | K3: NAVAJO | L3: PIMA | M3: PINAL | N3: SANTA CRUZ | O3: YAVAPAI | P3: YUMA | Q3: Total
A4: 0 | B4: 0 | C4: 0 | D4: 2 | E4: 0 | F4: 0 | G4: 0 | H4: 0 | I4: 70 | J4: 0 | K4: 0 | L4: 9 | M4: 16 | N4: 0 | O4: 2 | P4: 0 | Q4: 99
A5: 1 | B5: 0 | C5: 3 | D5: 1 | E5: 0 | F5: 0 | G5: 0 | H5: 0 | I5: 174 | J5: 4 | K5: 1 | L5: 22 | M5: 13 | N5: 1 | O5: 1 | P5: 3 | Q5: 223 | T5: =0+365*7+1 -> 2556
A6: 2 | B6: 1 | C6: 1 | D6: 1 | E6: 0 | F6: 0 | G6: 0 | H6: 0 | I6: 174 | J6: 3 | K6: 1 | L6: 28 | M6: 18 | N6: 1 | O6: 5 | P6: 2 | Q6: 235 | R6: JAN. | S6: =SUM(I$4:I$7)+(6/7)*I$8 -> 677 | T6: =31+365*7+1 -> 2587 | V6: =SUM(L$4:L$7)+(6/7)*L$8 -> 101 | W6: =SUM(M$4:M$7)+(6/7)*M$8 -> 83.285714 | AA6: =SUM(Q$4:Q$7)+(6/7)*Q$8 -> 930
A7: 3 | B7: 2 | C7: 4 | D7: 1 | E7: 0 | F7: 1 | G7: 0 | H7: 1 | I7: 139 | J7: 10 | K7: 2 | L7: 24 | M7: 20 | N7: 2 | O7: 5 | P7: 0 | Q7: 211 | R7: FEB. | S7: =(1/7)*I$8+SUM(I$9:I$11)+(7/7)*I$12 -> 597 | T7: =T6+28+1 -> 2616 | V7: =(1/7)*L$8+SUM(L$9:L$11)+(7/7)*L$12 -> 110 | W7: =(1/7)*M$8+SUM(M$9:M$11)+(7/7)*M$12 -> 71.714286 | AA7: =(1/7)*Q$8+SUM(Q$9:Q$11)+(7/7)*Q$12 -> 830
A8: 4 | B8: 0 | C8: 0 | D8: 1 | E8: 0 | F8: 0 | G8: 0 | H8: 0 | I8: 140 | J8: 4 | K8: 2 | L8: 21 | M8: 19 | N8: 0 | O8: 1 | P8: 1 | Q8: 189 | R8: MAR. | S8: =(0/7)*I$12+SUM(I$13:I$16)+(3/7)*I$17 -> 463.42857 | T8: =T7+31 -> 2647 | V8: =(0/7)*L$12+SUM(L$13:L$16)+(3/7)*L$17 -> 92.571429 | W8: =(0/7)*M$12+SUM(M$13:M$16)+(3/7)*M$17 -> 36.285714 | AA8: =(0/7)*Q$12+SUM(Q$13:Q$16)+(3/7)*Q$17 -> 635.28571
A9: 5 | B9: 0 | C9: 1 | D9: 1 | E9: 1 | F9: 1 | G9: 0 | H9: 0 | I9: 158 | J9: 4 | K9: 2 | L9: 24 | M9: 19 | N9: 1 | O9: 0 | P9: 0 | Q9: 212 | R9: APR. | S9: =(4/7)*I$17+SUM(I$18:I$20)+(5/7)*I$21 -> 305.57143 | T9: =T8+30 -> 2677 | V9: =(4/7)*L$17+SUM(L$18:L$20)+(5/7)*L$21 -> 82.571429 | W9: =(4/7)*M$17+SUM(M$18:M$20)+(5/7)*M$21 -> 45.857143 | AA9: =(4/7)*Q$17+SUM(Q$18:Q$20)+(5/7)*Q$21 -> 475.71429
A10: 6 | B10: 0 | C10: 1 | D10: 0 | E10: 1 | F10: 1 | G10: 0 | H10: 1 | I10: 136 | J10: 1 | K10: 1 | L10: 23 | M10: 21 | N10: 1 | O10: 0 | P10: 3 | Q10: 190 | R10: MAY | S10: =(2/7)*I$21+SUM(I$22:I$25)+(1/7)*I$26 -> 415.42857 | T10: =T9+31 -> 2708 | V10: =(2/7)*L$21+SUM(L$22:L$25)+(1/7)*L$26 -> 102.85714 | W10: =(2/7)*M$21+SUM(M$22:M$25)+(1/7)*M$26 -> 71.428571 | AA10: =(2/7)*Q$21+SUM(Q$22:Q$25)+(1/7)*Q$26 -> 630.57143
A11: 7 | B11: 0 | C11: 0 | D11: 0 | E11: 0 | F11: 0 | G11: 0 | H11: 0 | I11: 136 | J11: 7 | K11: 2 | L11: 31 | M11: 14 | N11: 0 | O11: 2 | P11: 3 | Q11: 195 | R11: JUN. | S11: =(6/7)*I$26+SUM(I$27:I$29)+(3/7)*I$30 -> 500.71429 | T11: =T10+30 -> 2738 | V11: =(6/7)*L$26+SUM(L$27:L$29)+(3/7)*L$30 -> 122.28571 | W11: =(6/7)*M$26+SUM(M$27:M$29)+(3/7)*M$30 -> 77.571429 | AA11: =(6/7)*Q$26+SUM(Q$27:Q$29)+(3/7)*Q$30 -> 747.14286
A12: 8 | B12: 0 | C12: 0 | D12: 0 | E12: 5 | F12: 0 | G12: 0 | H12: 1 | I12: 147 | J12: 3 | K12: 0 | L12: 29 | M12: 15 | N12: 3 | O12: 2 | P12: 1 | Q12: 206 | R12: JULY | S12: =(4/7)*I$30+SUM(I$31:I$33)+(6/7)*I$34 -> 535.42857 | T12: =T11+31 -> 2769 | V12: =(4/7)*L$30+SUM(L$31:L$33)+(6/7)*L$34 -> 125.28571 | W12: =(4/7)*M$30+SUM(M$31:M$33)+(6/7)*M$34 -> 87.857143 | AA12: =(4/7)*Q$30+SUM(Q$31:Q$33)+(6/7)*Q$34 -> 800.28571
A13: 9 | B13: 1 | C13: 2 | D13: 0 | E13: 2 | F13: 0 | G13: 0 | H13: 2 | I13: 139 | J13: 1 | K13: 1 | L13: 23 | M13: 15 | N13: 0 | O13: 4 | P13: 1 | Q13: 191 | R13: AUG. | S13: =(1/7)*I$34+SUM(I$35:I$38)+(2/7)*I$39 -> 735 | T13: =T12+31 -> 2800 | V13: =(1/7)*L$34+SUM(L$35:L$38)+(2/7)*L$39 -> 164.57143 | W13: =(1/7)*M$34+SUM(M$35:M$38)+(2/7)*M$39 -> 99.857143 | AA13: =(1/7)*Q$34+SUM(Q$35:Q$38)+(2/7)*Q$39 -> 1067.1429
A14: 10 | B14: 1 | C14: 1 | D14: 0 | E14: 0 | F14: 0 | G14: 0 | H14: 1 | I14: 125 | J14: 3 | K14: 0 | L14: 34 | M14: 8 | N14: 0 | O14: 2 | P14: 0 | Q14: 175 | R14: SEP. | S14: =(5/7)*I$39+SUM(I$40:I$42)+(4/7)*I$43 -> 860 | T14: =T13+30 -> 2830 | V14: =(5/7)*L$39+SUM(L$40:L$42)+(4/7)*L$43 -> 143.14286 | W14: =(5/7)*M$39+SUM(M$40:M$42)+(4/7)*M$43 -> 118 | AA14: =(5/7)*Q$39+SUM(Q$40:Q$42)+(4/7)*Q$43 -> 1188.2857
A15: 11 | B15: 0 | C15: 1 | D15: 1 | E15: 1 | F15: 1 | G15: 1 | H15: 0 | I15: 104 | J15: 3 | K15: 0 | L15: 17 | M15: 8 | N15: 1 | O15: 1 | P15: 2 | Q15: 141 | R15: OCT. | S15: =(3/7)*I$43+SUM(I$44:I$46)+(7/7)*I$47 -> 882.42857 | T15: =T14+31 -> 2861 | V15: =(3/7)*L$43+SUM(L$44:L$46)+(7/7)*L$47 -> 127.71429 | W15: =(3/7)*M$43+SUM(M$44:M$46)+(7/7)*M$47 -> 112.14286 | AA15: =(3/7)*Q$43+SUM(Q$44:Q$46)+(7/7)*Q$47 -> 1175.5714
A16: 12 | B16: 0 | C16: 1 | D16: 0 | E16: 0 | F16: 1 | G16: 0 | H16: 0 | I16: 71 | J16: 2 | K16: 0 | L16: 10 | M16: 4 | N16: 0 | O16: 1 | P16: 1 | Q16: 91 | R16: NOV. | S16: =(0/7)*I$47+SUM(I$48:I$51)+(2/7)*I$52 -> 1035.5714 | T16: =T15+30 -> 2891 | V16: =(0/7)*L$47+SUM(L$48:L$51)+(2/7)*L$52 -> 162.42857 | W16: =(0/7)*M$47+SUM(M$48:M$51)+(2/7)*M$52 -> 121.71429 | AA16: =(0/7)*Q$47+SUM(Q$48:Q$51)+(2/7)*Q$52 -> 1382.8571
A17: 13 | B17: 0 | C17: 0 | D17: 2 | E17: 0 | F17: 0 | G17: 0 | H17: 1 | I17: 57 | J17: 1 | K17: 0 | L17: 20 | M17: 3 | N17: 2 | O17: 0 | P17: 1 | Q17: 87 | R17: DEC. | S17: =(5/7)*I$52+SUM(I$53:I$55)+(7/7)*I$56 -> 1150.4286 | T17: =T16+31 -> 2922 | V17: =(5/7)*L$52+SUM(L$53:L$55)+(7/7)*L$56 -> 165.57143 | W17: =(5/7)*M$52+SUM(M$53:M$55)+(7/7)*M$56 -> 162.28571 | AA17: =(5/7)*Q$52+SUM(Q$53:Q$55)+(7/7)*Q$56 -> 1560.1429
A18: 14 | B18: 1 | C18: 0 | D18: 2 | E18: 1 | F18: 0 | G18: 0 | H18: 0 | I18: 70 | J18: 1 | K18: 0 | L18: 16 | M18: 10 | N18: 1 | O18: 1 | P18: 0 | Q18: 103 | R18: toal | S18: =SUM(S6:S17) -> 8158 | V18: =SUM(V6:V17) -> 1500 | W18: =SUM(W6:W17) -> 1088 | AA18: =SUM(AA6:AA17) -> 11423
A19: 15 | B19: 0 | C19: 0 | D19: 2 | E19: 2 | F19: 0 | G19: 0 | H19: 0 | I19: 73 | J19: 4 | K19: 4 | L19: 21 | M19: 16 | N19: 1 | O19: 0 | P19: 0 | Q19: 123
A20: 16 | B20: 1 | C20: 0 | D20: 3 | E20: 2 | F20: 0 | G20: 0 | H20: 1 | I20: 70 | J20: 1 | K20: 0 | L20: 17 | M20: 11 | N20: 1 | O20: 3 | P20: 0 | Q20: 110
A21: 17 | B21: 1 | C21: 2 | D21: 1 | E21: 1 | F21: 0 | G21: 0 | H21: 0 | I21: 84 | J21: 2 | K21: 0 | L21: 24 | M21: 10 | N21: 0 | O21: 1 | P21: 0 | Q21: 126
A22: 18 | B22: 0 | C22: 1 | D22: 0 | E22: 1 | F22: 0 | G22: 0 | H22: 1 | I22: 86 | J22: 4 | K22: 0 | L22: 20 | M22: 21 | N22: 0 | O22: 1 | P22: 0 | Q22: 135
A23: 19 | B23: 0 | C23: 2 | D23: 0 | E23: 2 | F23: 0 | G23: 0 | H23: 0 | I23: 92 | J23: 5 | K23: 0 | L23: 20 | M23: 16 | N23: 1 | O23: 1 | P23: 0 | Q23: 139
A24: 20 | B24: 1 | C24: 0 | D24: 1 | E24: 2 | F24: 0 | G24: 0 | H24: 0 | I24: 111 | J24: 0 | K24: 2 | L24: 25 | M24: 17 | N24: 1 | O24: 4 | P24: 0 | Q24: 164
A25: 21 | B25: 0 | C25: 0 | D25: 1 | E25: 0 | F25: 0 | G25: 0 | H25: 0 | I25: 86 | J25: 3 | K25: 0 | L25: 27 | M25: 12 | N25: 0 | O25: 1 | P25: 2 | Q25: 132
A26: 22 | B26: 0 | C26: 0 | D26: 0 | E26: 0 | F26: 0 | G26: 1 | H26: 0 | I26: 115 | J26: 7 | K26: 1 | L26: 28 | M26: 18 | N26: 0 | O26: 2 | P26: 0 | Q26: 172
A27: 23 | B27: 0 | C27: 1 | D27: 2 | E27: 2 | F27: 0 | G27: 0 | H27: 0 | I27: 119 | J27: 1 | K27: 0 | L27: 33 | M27: 11 | N27: 0 | O27: 2 | P27: 3 | Q27: 174
A28: 24 | B28: 1 | C28: 1 | D28: 2 | E28: 0 | F28: 0 | G28: 0 | H28: 0 | I28: 128 | J28: 2 | K28: 1 | L28: 25 | M28: 20 | N28: 1 | O28: 0 | P28: 1 | Q28: 182
A29: 25 | B29: 0 | C29: 2 | D29: 1 | E29: 0 | F29: 1 | G29: 0 | H29: 0 | I29: 117 | J29: 7 | K29: 0 | L29: 30 | M29: 26 | N29: 1 | O29: 3 | P29: 0 | Q29: 188
A30: 26 | B30: 1 | C30: 1 | D30: 0 | E30: 0 | F30: 0 | G30: 0 | H30: 0 | I30: 89 | J30: 2 | K30: 1 | L30: 24 | M30: 12 | N30: 0 | O30: 0 | P30: 0 | Q30: 130
... A56: 52 | B56: 1 | C56: 3 | D56: 2 | E56: 3 | F56: 1 | G56: 0 | H56: 1 | I56: 196 | J56: 2 | K56: 1 | L56: 22 | M56: 30 | N56: 1 | O56: 1 | P56: 0 | Q56: 264
A57: Total | B57: 30 | C57: 55 | D57: 50 | E57: 59 | F57: 26 | G57: 3 | H57: 16 | I57: 8158 | J57: 190 | K57: 61 | L57: 1500 | M57: 1088 | N57: 37 | O57: 100 | P57: 50 | Q57: 11423

Sheet CALENDAR YEAR 2019
A1: CALENDAR YEAR 2019
A2: EVENT DATE by CALENDAR WEEK | B2: COUNTY | S2: Maricopa | V2: Pima | W2: Pinal | AA2: AZ
B3: APACHE | C3: COCHISE | D3: COCONINO | E3: GILA | F3: GRAHAM | G3: GREENLEE | H3: LA PAZ | I3: MARICOPA | J3: MOHAVE | K3: NAVAJO | L3: PIMA | M3: PINAL | N3: SANTA CRUZ | O3: YAVAPAI | P3: YUMA | Q3: Total
A4: 0 | B4: 0 | C4: 1 | D4: 2 | E4: 0 | F4: 0 | G4: 0 | H4: 0 | I4: 96 | J4: 0 | K4: 1 | L4: 9 | M4: 7 | N4: 0 | O4: 1 | P4: 1 | Q4: 118
A5: 1 | B5: 0 | C5: 0 | D5: 2 | E5: 2 | F5: 0 | G5: 0 | H5: 0 | I5: 118 | J5: 1 | K5: 2 | L5: 23 | M5: 17 | N5: 0 | O5: 4 | P5: 0 | Q5: 169 | T5: =0+365*6+1 -> 2191
A6: 2 | B6: 0 | C6: 2 | D6: 0 | E6: 2 | F6: 1 | G6: 0 | H6: 0 | I6: 133 | J6: 3 | K6: 0 | L6: 23 | M6: 9 | N6: 0 | O6: 5 | P6: 4 | Q6: 182 | R6: JAN. | S6: =SUM(I$4:I$7)+(5/7)*I$8 -> 555 | T6: =31+365*6+1 -> 2222 | V6: =SUM(L$4:L$7)+(5/7)*L$8 -> 85.714286 | W6: =SUM(M$4:M$7)+(5/7)*M$8 -> 52.142857 | AA6: =SUM(Q$4:Q$7)+(5/7)*Q$8 -> 745.57143
A7: 3 | B7: 1 | C7: 0 | D7: 2 | E7: 1 | F7: 0 | G7: 0 | H7: 0 | I7: 123 | J7: 0 | K7: 0 | L7: 15 | M7: 12 | N7: 2 | O7: 2 | P7: 0 | Q7: 158 | R7: FEB. | S7: =(2/7)*I$8+SUM(I$9:I$11)+(5/7)*I$12 -> 440.42857 | T7: =T6+28 -> 2250 | V7: =(2/7)*L$8+SUM(L$9:L$11)+(5/7)*L$12 -> 111.85714 | W7: =(2/7)*M$8+SUM(M$9:M$11)+(5/7)*M$12 -> 57.571429 | AA7: =(2/7)*Q$8+SUM(Q$9:Q$11)+(5/7)*Q$12 -> 658
A8: 4 | B8: 1 | C8: 2 | D8: 1 | E8: 3 | F8: 0 | G8: 0 | H8: 0 | I8: 119 | J8: 2 | K8: 1 | L8: 22 | M8: 10 | N8: 0 | O8: 3 | P8: 2 | Q8: 166 | R8: MAR. | S8: =(2/7)*I$12+SUM(I$13:I$16)+(1/7)*I$17 -> 567.57143 | T8: =T7+31 -> 2281 | V8: =(2/7)*L$12+SUM(L$13:L$16)+(1/7)*L$17 -> 127.57143 | W8: =(2/7)*M$12+SUM(M$13:M$16)+(1/7)*M$17 -> 66.571429 | AA8: =(2/7)*Q$12+SUM(Q$13:Q$16)+(1/7)*Q$17 -> 811.42857
A9: 5 | B9: 1 | C9: 1 | D9: 3 | E9: 0 | F9: 0 | G9: 0 | H9: 1 | I9: 103 | J9: 2 | K9: 1 | L9: 21 | M9: 15 | N9: 0 | O9: 2 | P9: 0 | Q9: 150 | R9: APR. | S9: =(6/7)*I$17+SUM(I$18:I$20)+(3/7)*I$21 -> 514 | T9: =T8+30 -> 2311 | V9: =(6/7)*L$17+SUM(L$18:L$20)+(3/7)*L$21 -> 115.71429 | W9: =(6/7)*M$17+SUM(M$18:M$20)+(3/7)*M$21 -> 56.714286 | AA9: =(6/7)*Q$17+SUM(Q$18:Q$20)+(3/7)*Q$21 -> 749.71429
A10: 6 | B10: 2 | C10: 2 | D10: 1 | E10: 3 | F10: 0 | G10: 0 | H10: 0 | I10: 111 | J10: 1 | K10: 2 | L10: 36 | M10: 16 | N10: 1 | O10: 4 | P10: 2 | Q10: 181 | R10: MAY | S10: =(4/7)*I$21+SUM(I$22:I$24)+(6/7)*I$25 -> 545.28571 | T10: =T9+31 -> 2342 | V10: =(4/7)*L$21+SUM(L$22:L$24)+(6/7)*L$25 -> 115.57143 | W10: =(4/7)*M$21+SUM(M$22:M$24)+(6/7)*M$25 -> 75.714286 | AA10: =(4/7)*Q$21+SUM(Q$22:Q$24)+(6/7)*Q$25 -> 797.71429
A11: 7 | B11: 0 | C11: 1 | D11: 0 | E11: 1 | F11: 0 | G11: 0 | H11: 1 | I11: 91 | J11: 2 | K11: 1 | L11: 25 | M11: 13 | N11: 0 | O11: 0 | P11: 1 | Q11: 136 | R11: JUN. | S11: =(1/7)*I$25+SUM(I$26:I$29)+(1/7)*I$30 -> 556.14286 | T11: =T10+30 -> 2372 | V11: =(1/7)*L$25+SUM(L$26:L$29)+(1/7)*L$30 -> 122 | W11: =(1/7)*M$25+SUM(M$26:M$29)+(1/7)*M$30 -> 77.714286 | AA11: =(1/7)*Q$25+SUM(Q$26:Q$29)+(1/7)*Q$30 -> 818.28571
A12: 8 | B12: 0 | C12: 2 | D12: 1 | E12: 1 | F12: 0 | G12: 0 | H12: 1 | I12: 142 | J12: 1 | K12: 3 | L12: 33 | M12: 15 | N12: 0 | O12: 0 | P12: 2 | Q12: 201 | R12: JULY | S12: =(6/7)*I$30+SUM(I$31:I$33)+(4/7)*I$34 -> 657.85714 | T12: =T11+31 -> 2403 | V12: =(6/7)*L$30+SUM(L$31:L$33)+(4/7)*L$34 -> 146.57143 | W12: =(6/7)*M$30+SUM(M$31:M$33)+(4/7)*M$34 -> 81.571429 | AA12: =(6/7)*Q$30+SUM(Q$31:Q$33)+(4/7)*Q$34 -> 943.28571
A13: 9 | B13: 1 | C13: 2 | D13: 2 | E13: 2 | F13: 0 | G13: 0 | H13: 0 | I13: 113 | J13: 3 | K13: 2 | L13: 29 | M13: 11 | N13: 1 | O13: 1 | P13: 1 | Q13: 168 | R13: AUG. | S13: =(3/7)*I$34+SUM(I$35:I$37)+(7/7)*I$38 -> 666.71429 | T13: =T12+31 -> 2434 | V13: =(3/7)*L$34+SUM(L$35:L$37)+(7/7)*L$38 -> 143 | W13: =(3/7)*M$34+SUM(M$35:M$37)+(7/7)*M$38 -> 80 | AA13: =(3/7)*Q$34+SUM(Q$35:Q$37)+(7/7)*Q$38 -> 971
A14: 10 | B14: 0 | C14: 0 | D14: 1 | E14: 3 | F14: 0 | G14: 0 | H14: 0 | I14: 142 | J14: 1 | K14: 2 | L14: 24 | M14: 24 | N14: 0 | O14: 2 | P14: 2 | Q14: 201 | R14: SEP. | S14: =(0/7)*I$38+SUM(I$39:I$42)+(2/7)*I$43 -> 575 | T14: =T13+30 -> 2464 | V14: =(0/7)*L$38+SUM(L$39:L$42)+(2/7)*L$43 -> 100.14286 | W14: =(0/7)*M$38+SUM(M$39:M$42)+(2/7)*M$43 -> 65.285714 | AA14: =(0/7)*Q$38+SUM(Q$39:Q$42)+(2/7)*Q$43 -> 798.28571
A15: 11 | B15: 0 | C15: 1 | D15: 2 | E15: 0 | F15: 0 | G15: 0 | H15: 1 | I15: 127 | J15: 0 | K15: 2 | L15: 27 | M15: 17 | N15: 0 | O15: 2 | P15: 0 | Q15: 179 | R15: OCT. | S15: =(5/7)*I$43+SUM(I$44:I$46)+(5/7)*I$47 -> 631.71429 | T15: =T14+31 -> 2495 | V15: =(5/7)*L$43+SUM(L$44:L$46)+(5/7)*L$47 -> 118.42857 | W15: =(5/7)*M$43+SUM(M$44:M$46)+(5/7)*M$47 -> 91.857143 | AA15: =(5/7)*Q$43+SUM(Q$44:Q$46)+(5/7)*Q$47 -> 902.42857
A16: 12 | B16: 0 | C16: 2 | D16: 2 | E16: 1 | F16: 1 | G16: 0 | H16: 0 | I16: 127 | J16: 0 | K16: 1 | L16: 35 | M16: 8 | N16: 0 | O16: 4 | P16: 0 | Q16: 181 | R16: NOV. | S16: =(2/7)*I$47+SUM(I$48:I$50)+(7/7)*I$51 -> 806.28571 | T16: =T15+30 -> 2525 | V16: =(2/7)*L$47+SUM(L$48:L$50)+(7/7)*L$51 -> 123.42857 | W16: =(2/7)*M$47+SUM(M$48:M$50)+(7/7)*M$51 -> 121.85714 | AA16: =(2/7)*Q$47+SUM(Q$48:Q$50)+(7/7)*Q$51 -> 1115.2857
A17: 13 | B17: 0 | C17: 0 | D17: 1 | E17: 3 | F17: 0 | G17: 0 | H17: 0 | I17: 126 | J17: 1 | K17: 1 | L17: 22 | M17: 16 | N17: 1 | O17: 3 | P17: 1 | Q17: 175 | R17: DEC. | S17: =(0/7)*I$51+SUM(I$52:I$55)+(7/7)*I$56 -> 754 | T17: =T16+31 -> 2556 | V17: =(0/7)*L$51+SUM(L$52:L$55)+(7/7)*L$56 -> 131 | W17: =(0/7)*M$51+SUM(M$52:M$55)+(7/7)*M$56 -> 118 | AA17: =(0/7)*Q$51+SUM(Q$52:Q$55)+(7/7)*Q$56 -> 1059
A18: 14 | B18: 1 | C18: 3 | D18: 0 | E18: 0 | F18: 0 | G18: 0 | H18: 1 | I18: 114 | J18: 3 | K18: 4 | L18: 38 | M18: 12 | N18: 0 | O18: 1 | P18: 2 | Q18: 179 | R18: toal | S18: =SUM(S6:S17) -> 7270 | V18: =SUM(V6:V17) -> 1441 | W18: =SUM(W6:W17) -> 945 | AA18: =SUM(AA6:AA17) -> 10370
A19: 15 | B19: 1 | C19: 1 | D19: 2 | E19: 4 | F19: 0 | G19: 0 | H19: 0 | I19: 123 | J19: 2 | K19: 3 | L19: 15 | M19: 10 | N19: 0 | O19: 3 | P19: 2 | Q19: 166
A20: 16 | B20: 2 | C20: 0 | D20: 0 | E20: 1 | F20: 0 | G20: 0 | H20: 0 | I20: 109 | J20: 3 | K20: 2 | L20: 31 | M20: 12 | N20: 0 | O20: 1 | P20: 2 | Q20: 163
A21: 17 | B21: 1 | C21: 1 | D21: 1 | E21: 1 | F21: 2 | G21: 0 | H21: 0 | I21: 140 | J21: 4 | K21: 4 | L21: 30 | M21: 21 | N21: 0 | O21: 6 | P21: 3 | Q21: 214
A22: 18 | B22: 1 | C22: 0 | D22: 1 | E22: 0 | F22: 1 | G22: 0 | H22: 2 | I22: 147 | J22: 5 | K22: 0 | L22: 37 | M22: 23 | N22: 1 | O22: 2 | P22: 0 | Q22: 220
A23: 19 | B23: 0 | C23: 1 | D23: 0 | E23: 1 | F23: 0 | G23: 0 | H23: 0 | I23: 133 | J23: 3 | K23: 1 | L23: 29 | M23: 21 | N23: 0 | O23: 4 | P23: 1 | Q23: 194
A24: 20 | B24: 0 | C24: 1 | D24: 1 | E24: 1 | F24: 0 | G24: 0 | H24: 0 | I24: 115 | J24: 1 | K24: 1 | L24: 17 | M24: 12 | N24: 0 | O24: 1 | P24: 0 | Q24: 150
A25: 21 | B25: 1 | C25: 5 | D25: 2 | E25: 1 | F25: 1 | G25: 0 | H25: 1 | I25: 82 | J25: 2 | K25: 2 | L25: 18 | M25: 9 | N25: 1 | O25: 1 | P25: 4 | Q25: 130
A26: 22 | B26: 0 | C26: 2 | D26: 0 | E26: 1 | F26: 0 | G26: 0 | H26: 2 | I26: 126 | J26: 2 | K26: 2 | L26: 30 | M26: 17 | N26: 1 | O26: 1 | P26: 1 | Q26: 185
A27: 23 | B27: 0 | C27: 0 | D27: 0 | E27: 0 | F27: 0 | G27: 0 | H27: 0 | I27: 113 | J27: 1 | K27: 1 | L27: 26 | M27: 16 | N27: 3 | O27: 3 | P27: 1 | Q27: 164
A28: 24 | B28: 0 | C28: 2 | D28: 1 | E28: 2 | F28: 0 | G28: 0 | H28: 0 | I28: 144 | J28: 6 | K28: 3 | L28: 30 | M28: 17 | N28: 3 | O28: 1 | P28: 1 | Q28: 210
A29: 25 | B29: 0 | C29: 2 | D29: 1 | E29: 3 | F29: 1 | G29: 1 | H29: 0 | I29: 145 | J29: 0 | K29: 2 | L29: 30 | M29: 24 | N29: 1 | O29: 4 | P29: 3 | Q29: 217
A30: 26 | B30: 1 | C30: 4 | D30: 0 | E30: 0 | F30: 1 | G30: 0 | H30: 0 | I30: 115 | J30: 2 | K30: 1 | L30: 24 | M30: 17 | N30: 0 | O30: 1 | P30: 0 | Q30: 166
... A56: 52 | B56: 0 | C56: 1 | D56: 0 | E56: 0 | F56: 0 | G56: 0 | H56: 0 | I56: 54 | J56: 0 | K56: 0 | L56: 5 | M56: 12 | N56: 0 | O56: 1 | P56: 0 | Q56: 73
A57: Total | B57: 43 | C57: 81 | D57: 52 | E57: 73 | F57: 17 | G57: 1 | H57: 22 | I57: 7270 | J57: 143 | K57: 69 | L57: 1441 | M57: 945 | N57: 24 | O57: 122 | P57: 67 | Q57: 10370

Sheet CALENDAR YEAR 2018
A1: CALENDAR YEAR 2018
A2: EVENT DATE by CALENDAR WEEK | B2: COUNTY | S2: Maricopa | V2: Pima | W2: Pinal | AA2: AZ
B3: APACHE | C3: COCHISE | D3: COCONINO | E3: GILA | F3: GRAHAM | G3: GREENLEE | H3: LA PAZ | I3: MARICOPA | J3: MOHAVE | K3: NAVAJO | L3: PIMA | M3: PINAL | N3: SANTA CRUZ | O3: YAVAPAI | P3: YUMA | Q3: Total
A4: 0 | B4: 1 | C4: 1 | D4: 1 | E4: 1 | F4: 0 | G4: 0 | H4: 0 | I4: 152 | J4: 2 | K4: 1 | L4: 22 | M4: 17 | N4: 0 | O4: 1 | P4: 0 | Q4: 199
A5: 1 | B5: 0 | C5: 0 | D5: 0 | E5: 1 | F5: 0 | G5: 0 | H5: 0 | I5: 178 | J5: 4 | K5: 2 | L5: 27 | M5: 15 | N5: 0 | O5: 0 | P5: 1 | Q5: 228 | T5: =0+365*5+1 -> 1826
A6: 2 | B6: 0 | C6: 0 | D6: 2 | E6: 2 | F6: 0 | G6: 0 | H6: 1 | I6: 146 | J6: 4 | K6: 1 | L6: 12 | M6: 15 | N6: 0 | O6: 0 | P6: 0 | Q6: 183 | R6: JAN. | S6: =SUM(I$4:I$7)+(4/7)*I$8 -> 702.71429 | T6: =31+365*5+1 -> 1857 | V6: =SUM(L$4:L$7)+(4/7)*L$8 -> 90.428571 | W6: =SUM(M$4:M$7)+(4/7)*M$8 -> 65.571429 | AA6: =SUM(Q$4:Q$7)+(4/7)*Q$8 -> 898.28571
A7: 3 | B7: 1 | C7: 0 | D7: 1 | E7: 0 | F7: 0 | G7: 0 | H7: 0 | I7: 153 | J7: 2 | K7: 1 | L7: 22 | M7: 14 | N7: 0 | O7: 3 | P7: 1 | Q7: 198 | R7: FEB. | S7: =(3/7)*I$8+SUM(I$9:I$11)+(4/7)*I$12 -> 437.57143 | T7: =T6+28 -> 1885 | V7: =(3/7)*L$8+SUM(L$9:L$11)+(4/7)*L$12 -> 83.857143 | W7: =(3/7)*M$8+SUM(M$9:M$11)+(4/7)*M$12 -> 34.857143 | AA7: =(3/7)*Q$8+SUM(Q$9:Q$11)+(4/7)*Q$12 -> 584.42857
A8: 4 | B8: 0 | C8: 1 | D8: 0 | E8: 0 | F8: 0 | G8: 0 | H8: 0 | I8: 129 | J8: 0 | K8: 2 | L8: 13 | M8: 8 | N8: 1 | O8: 3 | P8: 1 | Q8: 158 | R8: MAR. | S8: =(3/7)*I$12+SUM(I$13:I$15)+(7/7)*I$16 -> 428.71429 | T8: =T7+31 -> 1916 | V8: =(3/7)*L$12+SUM(L$13:L$15)+(7/7)*L$16 -> 71.714286 | W8: =(3/7)*M$12+SUM(M$13:M$15)+(7/7)*M$16 -> 36.571429 | AA8: =(3/7)*Q$12+SUM(Q$13:Q$15)+(7/7)*Q$16 -> 564.28571
A9: 5 | B9: 0 | C9: 0 | D9: 1 | E9: 1 | F9: 0 | G9: 0 | H9: 1 | I9: 115 | J9: 1 | K9: 0 | L9: 17 | M9: 10 | N9: 0 | O9: 2 | P9: 0 | Q9: 148 | R9: APR. | S9: =(0/7)*I$16+SUM(I$17:I$20)+(2/7)*I$21 -> 421 | T9: =T8+30 -> 1946 | V9: =(0/7)*L$16+SUM(L$17:L$20)+(2/7)*L$21 -> 59.428571 | W9: =(0/7)*M$16+SUM(M$17:M$20)+(2/7)*M$21 -> 47.428571 | AA9: =(0/7)*Q$16+SUM(Q$17:Q$20)+(2/7)*Q$21 -> 552
A10: 6 | B10: 0 | C10: 0 | D10: 0 | E10: 2 | F10: 0 | G10: 0 | H10: 0 | I10: 93 | J10: 2 | K10: 0 | L10: 21 | M10: 9 | N10: 1 | O10: 2 | P10: 0 | Q10: 130 | R10: MAY | S10: =(5/7)*I$21+SUM(I$22:I$24)+(5/7)*I$25 -> 481 | T10: =T9+31 -> 1977 | V10: =(5/7)*L$21+SUM(L$22:L$24)+(5/7)*L$25 -> 83.285714 | W10: =(5/7)*M$21+SUM(M$22:M$24)+(5/7)*M$25 -> 56.571429 | AA10: =(5/7)*Q$21+SUM(Q$22:Q$24)+(5/7)*Q$25 -> 663
A11: 7 | B11: 0 | C11: 0 | D11: 1 | E11: 2 | F11: 1 | G11: 0 | H11: 1 | I11: 108 | J11: 0 | K11: 2 | L11: 22 | M11: 5 | N11: 0 | O11: 3 | P11: 0 | Q11: 145 | R11: JUN. | S11: =(2/7)*I$25+SUM(I$26:I$28)+(7/7)*I$29 -> 430 | T11: =T10+30 -> 2007 | V11: =(2/7)*L$25+SUM(L$26:L$28)+(7/7)*L$29 -> 97.285714 | W11: =(2/7)*M$25+SUM(M$26:M$28)+(7/7)*M$29 -> 43 | AA11: =(2/7)*Q$25+SUM(Q$26:Q$28)+(7/7)*Q$29 -> 611
A12: 8 | B12: 1 | C12: 0 | D12: 2 | E12: 0 | F12: 0 | G12: 0 | H12: 0 | I12: 116 | J12: 0 | K12: 0 | L12: 32 | M12: 13 | N12: 0 | O12: 0 | P12: 0 | Q12: 164 | R12: JULY | S12: =(0/7)*I$29+SUM(I$30:I$33)+(3/7)*I$34 -> 494.57143 | T12: =T11+31 -> 2038 | V12: =(0/7)*L$29+SUM(L$30:L$33)+(3/7)*L$34 -> 103.28571 | W12: =(0/7)*M$29+SUM(M$30:M$33)+(3/7)*M$34 -> 52.857143 | AA12: =(0/7)*Q$29+SUM(Q$30:Q$33)+(3/7)*Q$34 -> 689.57143
A13: 9 | B13: 0 | C13: 2 | D13: 1 | E13: 0 | F13: 0 | G13: 0 | H13: 1 | I13: 114 | J13: 2 | K13: 0 | L13: 23 | M13: 10 | N13: 1 | O13: 0 | P13: 1 | Q13: 155 | R13: AUG. | S13: =(4/7)*I$34+SUM(I$35:I$37)+(6/7)*I$38 -> 448 | T13: =T12+31 -> 2069 | V13: =(4/7)*L$34+SUM(L$35:L$37)+(6/7)*L$38 -> 87.714286 | W13: =(4/7)*M$34+SUM(M$35:M$37)+(6/7)*M$38 -> 37.571429 | AA13: =(4/7)*Q$34+SUM(Q$35:Q$37)+(6/7)*Q$38 -> 609.85714
A14: 10 | B14: 0 | C14: 0 | D14: 0 | E14: 1 | F14: 1 | G14: 0 | H14: 0 | I14: 102 | J14: 1 | K14: 1 | L14: 14 | M14: 7 | N14: 0 | O14: 0 | P14: 0 | Q14: 127 | R14: SEP. | S14: =(1/7)*I$38+SUM(I$39:I$42)+(1/7)*I$43 -> 389.85714 | T14: =T13+30 -> 2099 | V14: =(1/7)*L$38+SUM(L$39:L$42)+(1/7)*L$43 -> 76.285714 | W14: =(1/7)*M$38+SUM(M$39:M$42)+(1/7)*M$43 -> 32 | AA14: =(1/7)*Q$38+SUM(Q$39:Q$42)+(1/7)*Q$43 -> 538
A15: 11 | B15: 0 | C15: 0 | D15: 0 | E15: 2 | F15: 0 | G15: 0 | H15: 0 | I15: 90 | J15: 2 | K15: 1 | L15: 10 | M15: 8 | N15: 0 | O15: 2 | P15: 2 | Q15: 117 | R15: OCT. | S15: =(6/7)*I$43+SUM(I$44:I$46)+(4/7)*I$47 -> 461.71429 | T15: =T14+31 -> 2130 | V15: =(6/7)*L$43+SUM(L$44:L$46)+(4/7)*L$47 -> 76 | W15: =(6/7)*M$43+SUM(M$44:M$46)+(4/7)*M$47 -> 51.857143 | AA15: =(6/7)*Q$43+SUM(Q$44:Q$46)+(4/7)*Q$47 -> 622.71429
A16: 12 | B16: 0 | C16: 0 | D16: 2 | E16: 0 | F16: 0 | G16: 0 | H16: 0 | I16: 73 | J16: 0 | K16: 0 | L16: 11 | M16: 6 | N16: 0 | O16: 0 | P16: 3 | Q16: 95 | R16: NOV. | S16: =(3/7)*I$47+SUM(I$48:I$50)+(6/7)*I$51 -> 362.42857 | T16: =T15+30 -> 2160 | V16: =(3/7)*L$47+SUM(L$48:L$50)+(6/7)*L$51 -> 75 | W16: =(3/7)*M$47+SUM(M$48:M$50)+(6/7)*M$51 -> 42.142857 | AA16: =(3/7)*Q$47+SUM(Q$48:Q$50)+(6/7)*Q$51 -> 523.42857
A17: 13 | B17: 2 | C17: 0 | D17: 1 | E17: 2 | F17: 0 | G17: 0 | H17: 1 | I17: 98 | J17: 1 | K17: 0 | L17: 9 | M17: 17 | N17: 0 | O17: 1 | P17: 0 | Q17: 132 | R17: DEC. | S17: =(1/7)*I$51+SUM(I$52:I$55)+(7/7)*I$56 -> 464.42857 | T17: =T16+31 -> 2191 | V17: =(1/7)*L$51+SUM(L$52:L$55)+(7/7)*L$56 -> 62.714286 | W17: =(1/7)*M$51+SUM(M$52:M$55)+(7/7)*M$56 -> 63.571429 | AA17: =(1/7)*Q$51+SUM(Q$52:Q$55)+(7/7)*Q$56 -> 630.42857
A18: 14 | B18: 0 | C18: 0 | D18: 1 | E18: 0 | F18: 1 | G18: 0 | H18: 1 | I18: 87 | J18: 0 | K18: 0 | L18: 18 | M18: 10 | N18: 0 | O18: 0 | P18: 1 | Q18: 119 | R18: toal | S18: =SUM(S6:S17) -> 5522 | V18: =SUM(V6:V17) -> 967 | W18: =SUM(W6:W17) -> 564 | AA18: =SUM(AA6:AA17) -> 7487
A19: 15 | B19: 2 | C19: 0 | D19: 1 | E19: 0 | F19: 0 | G19: 0 | H19: 0 | I19: 115 | J19: 0 | K19: 0 | L19: 15 | M19: 10 | N19: 0 | O19: 1 | P19: 0 | Q19: 144
A20: 16 | B20: 1 | C20: 1 | D20: 0 | E20: 0 | F20: 0 | G20: 0 | H20: 1 | I20: 97 | J20: 1 | K20: 0 | L20: 12 | M20: 9 | N20: 0 | O20: 2 | P20: 1 | Q20: 125
A21: 17 | B21: 0 | C21: 1 | D21: 0 | E21: 0 | F21: 0 | G21: 0 | H21: 0 | I21: 84 | J21: 1 | K21: 1 | L21: 19 | M21: 5 | N21: 0 | O21: 1 | P21: 0 | Q21: 112
A22: 18 | B22: 0 | C22: 2 | D22: 1 | E22: 1 | F22: 0 | G22: 0 | H22: 1 | I22: 111 | J22: 3 | K22: 1 | L22: 15 | M22: 8 | N22: 0 | O22: 2 | P22: 0 | Q22: 145
A23: 19 | B23: 0 | C23: 2 | D23: 0 | E23: 1 | F23: 0 | G23: 0 | H23: 1 | I23: 109 | J23: 1 | K23: 0 | L23: 21 | M23: 13 | N23: 1 | O23: 1 | P23: 0 | Q23: 150
A24: 20 | B24: 0 | C24: 1 | D24: 2 | E24: 1 | F24: 0 | G24: 1 | H24: 0 | I24: 136 | J24: 4 | K24: 0 | L24: 18 | M24: 22 | N24: 0 | O24: 2 | P24: 1 | Q24: 188
A25: 21 | B25: 1 | C25: 2 | D25: 3 | E25: 0 | F25: 1 | G25: 0 | H25: 0 | I25: 91 | J25: 2 | K25: 2 | L25: 22 | M25: 14 | N25: 0 | O25: 2 | P25: 0 | Q25: 140
A26: 22 | B26: 0 | C26: 1 | D26: 0 | E26: 0 | F26: 1 | G26: 0 | H26: 0 | I26: 106 | J26: 0 | K26: 4 | L26: 25 | M26: 6 | N26: 1 | O26: 0 | P26: 1 | Q26: 145
A27: 23 | B27: 0 | C27: 2 | D27: 0 | E27: 1 | F27: 0 | G27: 0 | H27: 0 | I27: 85 | J27: 4 | K27: 0 | L27: 23 | M27: 9 | N27: 0 | O27: 1 | P27: 1 | Q27: 126
A28: 24 | B28: 0 | C28: 2 | D28: 1 | E28: 2 | F28: 0 | G28: 0 | H28: 0 | I28: 109 | J28: 2 | K28: 1 | L28: 20 | M28: 7 | N28: 0 | O28: 0 | P28: 0 | Q28: 144
A29: 25 | B29: 0 | C29: 2 | D29: 2 | E29: 2 | F29: 0 | G29: 0 | H29: 1 | I29: 104 | J29: 2 | K29: 1 | L29: 23 | M29: 17 | N29: 0 | O29: 2 | P29: 0 | Q29: 156
A30: 26 | B30: 0 | C30: 0 | D30: 0 | E30: 0 | F30: 1 | G30: 0 | H30: 0 | I30: 99 | J30: 1 | K30: 0 | L30: 24 | M30: 8 | N30: 1 | O30: 2 | P30: 0 | Q30: 136
... A56: 52 | B56: 1 | C56: 0 | D56: 0 | E56: 0 | F56: 0 | G56: 0 | H56: 0 | I56: 8 | J56: 0 | K56: 0 | L56: 4 | M56: 3 | N56: 1 | O56: 1 | P56: 0 | Q56: 18
A57: Total | B57: 24 | C57: 45 | D57: 46 | E57: 45 | F57: 17 | G57: 1 | H57: 14 | I57: 5522 | J57: 80 | K57: 41 | L57: 967 | M57: 564 | N57: 21 | O57: 73 | P57: 27 | Q57: 7487

Sheet CALENDAR YEAR 2017
A1: CALENDAR YEAR 2017
A2: EVENT DATE by CALENDAR WEEK | B2: COUNTY | S2: Maricopa | V2: Pima | W2: Pinal | AA2: AZ
B3: APACHE | C3: COCHISE | D3: COCONINO | E3: GILA | F3: GRAHAM | G3: GREENLEE | H3: LA PAZ | I3: MARICOPA | J3: MOHAVE | K3: NAVAJO | L3: PIMA | M3: PINAL | N3: SANTA CRUZ | O3: YAVAPAI | P3: YUMA | Q3: Total
A4: 1 | B4: 0 | C4: 2 | D4: 0 | E4: 0 | F4: 0 | G4: 1 | H4: 0 | I4: 79 | J4: 1 | K4: 0 | L4: 21 | M4: 5 | N4: 0 | O4: 1 | P4: 0 | Q4: 110
A5: 2 | B5: 3 | C5: 1 | D5: 0 | E5: 2 | F5: 0 | G5: 0 | H5: 1 | I5: 88 | J5: 2 | K5: 1 | L5: 18 | M5: 10 | N5: 0 | O5: 1 | P5: 0 | Q5: 127 | T5: =0+365*4+1 -> 1461
A6: 3 | B6: 0 | C6: 0 | D6: 0 | E6: 1 | F6: 0 | G6: 0 | H6: 0 | I6: 90 | J6: 0 | K6: 0 | L6: 22 | M6: 17 | N6: 0 | O6: 2 | P6: 0 | Q6: 132 | R6: JAN. | S6: =SUM(I$4:I$7)+(3/7)*I$8 -> 370.42857 | T6: =31+365*4+1 -> 1492 | V6: =SUM(L$4:L$7)+(3/7)*L$8 -> 83.857143 | W6: =SUM(M$4:M$7)+(3/7)*M$8 -> 47.428571 | AA6: =SUM(Q$4:Q$7)+(3/7)*Q$8 -> 532.14286
A7: 4 | B7: 0 | C7: 2 | D7: 1 | E7: 0 | F7: 0 | G7: 0 | H7: 0 | I7: 80 | J7: 1 | K7: 2 | L7: 13 | M7: 12 | N7: 0 | O7: 0 | P7: 2 | Q7: 113 | R7: FEB. | S7: =(4/7)*I$8+SUM(I$9:I$11)+(3/7)*I$12 -> 290 | T7: =T6+28 -> 1520 | V7: =(4/7)*L$8+SUM(L$9:L$11)+(3/7)*L$12 -> 64.142857 | W7: =(4/7)*M$8+SUM(M$9:M$11)+(3/7)*M$12 -> 24.571429 | AA7: =(4/7)*Q$8+SUM(Q$9:Q$11)+(3/7)*Q$12 -> 416
A8: 5 | B8: 1 | C8: 0 | D8: 1 | E8: 0 | F8: 1 | G8: 0 | H8: 0 | I8: 78 | J8: 0 | K8: 3 | L8: 23 | M8: 8 | N8: 0 | O8: 2 | P8: 0 | Q8: 117 | R8: MAR. | S8: =(4/7)*I$12+SUM(I$13:I$15)+(6/7)*I$16 -> 264 | T8: =T7+31 -> 1551 | V8: =(4/7)*L$12+SUM(L$13:L$15)+(6/7)*L$16 -> 74.285714 | W8: =(4/7)*M$12+SUM(M$13:M$15)+(6/7)*M$16 -> 42 | AA8: =(4/7)*Q$12+SUM(Q$13:Q$15)+(6/7)*Q$16 -> 408.71429
A9: 6 | B9: 1 | C9: 1 | D9: 0 | E9: 1 | F9: 0 | G9: 0 | H9: 2 | I9: 67 | J9: 1 | K9: 1 | L9: 15 | M9: 5 | N9: 0 | O9: 1 | P9: 2 | Q9: 97 | R9: APR. | S9: =(1/7)*I$16+SUM(I$17:I$20)+(1/7)*I$21 -> 305.71429 | T9: =T8+30 -> 1581 | V9: =(1/7)*L$16+SUM(L$17:L$20)+(1/7)*L$21 -> 87.428571 | W9: =(1/7)*M$16+SUM(M$17:M$20)+(1/7)*M$21 -> 36.571429 | AA9: =(1/7)*Q$16+SUM(Q$17:Q$20)+(1/7)*Q$21 -> 457.14286
A10: 7 | B10: 1 | C10: 0 | D10: 0 | E10: 3 | F10: 0 | G10: 0 | H10: 2 | I10: 81 | J10: 1 | K10: 2 | L10: 17 | M10: 7 | N10: 3 | O10: 0 | P10: 1 | Q10: 118 | R10: MAY | S10: =(6/7)*I$21+SUM(I$22:I$24)+(4/7)*I$25 -> 310.71429 | T10: =T9+31 -> 1612 | V10: =(6/7)*L$21+SUM(L$22:L$24)+(4/7)*L$25 -> 67 | W10: =(6/7)*M$21+SUM(M$22:M$24)+(4/7)*M$25 -> 39.285714 | AA10: =(6/7)*Q$21+SUM(Q$22:Q$24)+(4/7)*Q$25 -> 442.71429
A11: 8 | B11: 1 | C11: 0 | D11: 0 | E11: 1 | F11: 0 | G11: 0 | H11: 0 | I11: 70 | J11: 0 | K11: 0 | L11: 13 | M11: 5 | N11: 0 | O11: 2 | P11: 1 | Q11: 93 | R11: JUN. | S11: =(3/7)*I$25+SUM(I$26:I$28)+(6/7)*I$29 -> 290.85714 | T11: =T10+30 -> 1642 | V11: =(3/7)*L$25+SUM(L$26:L$28)+(6/7)*L$29 -> 63.857143 | W11: =(3/7)*M$25+SUM(M$26:M$28)+(6/7)*M$29 -> 33.571429 | AA11: =(3/7)*Q$25+SUM(Q$26:Q$28)+(6/7)*Q$29 -> 417.28571
A12: 9 | B12: 1 | C12: 1 | D12: 0 | E12: 3 | F12: 0 | G12: 0 | H12: 1 | I12: 64 | J12: 0 | K12: 2 | L12: 14 | M12: 7 | N12: 1 | O12: 2 | P12: 0 | Q12: 96 | R12: JULY | S12: =(1/7)*I$29+SUM(I$30:I$33)+(2/7)*I$34 -> 345.57143 | T12: =T11+31 -> 1673 | V12: =(1/7)*L$29+SUM(L$30:L$33)+(2/7)*L$34 -> 105.42857 | W12: =(1/7)*M$29+SUM(M$30:M$33)+(2/7)*M$34 -> 33.857143 | AA12: =(1/7)*Q$29+SUM(Q$30:Q$33)+(2/7)*Q$34 -> 522.85714
A13: 10 | B13: 1 | C13: 1 | D13: 1 | E13: 1 | F13: 0 | G13: 0 | H13: 0 | I13: 74 | J13: 2 | K13: 1 | L13: 18 | M13: 12 | N13: 0 | O13: 1 | P13: 0 | Q13: 112 | R13: AUG. | S13: =(5/7)*I$34+SUM(I$35:I$37)+(5/7)*I$38 -> 364.14286 | T13: =T12+31 -> 1704 | V13: =(5/7)*L$34+SUM(L$35:L$37)+(5/7)*L$38 -> 75.857143 | W13: =(5/7)*M$34+SUM(M$35:M$37)+(5/7)*M$38 -> 46.714286 | AA13: =(5/7)*Q$34+SUM(Q$35:Q$37)+(5/7)*Q$38 -> 522.28571
A14: 11 | B14: 1 | C14: 1 | D14: 0 | E14: 0 | F14: 0 | G14: 0 | H14: 1 | I14: 47 | J14: 0 | K14: 1 | L14: 15 | M14: 9 | N14: 0 | O14: 0 | P14: 0 | Q14: 75 | R14: SEP. | S14: =(2/7)*I$38+SUM(I$39:I$41)+(7/7)*I$42 -> 323.57143 | T14: =T13+30 -> 1734 | V14: =(2/7)*L$38+SUM(L$39:L$41)+(7/7)*L$42 -> 58.142857 | W14: =(2/7)*M$38+SUM(M$39:M$41)+(7/7)*M$42 -> 26 | AA14: =(2/7)*Q$38+SUM(Q$39:Q$41)+(7/7)*Q$42 -> 444.85714
